Workbook

Sheet Conciliacao
A1: Data | B1: Extrato Zig (Saques) | C1: Faturam Dinheiro | D1: Receitas Extraord | E1: Eventos | F1: Entradas Mútuos | G1: Desbloqueios Judiciais | H1: Extrato Bancário (Crédito) | I1: Diferenças (Contas a Receber) | J1: Custos Sem Parcelamento | K1: Custos Com Parcelamento | L1: Saídas Mútuos | M1: Bloqueios Judiciais | N1: Extrato Bancário (Débito) | O1: Diferenças (Contas a Pagar) | P1: Ajustes Conciliação | Q1: Conciliação | BE1: Coluna Auxiliar Data | BF1: Coluna Auxiliar Data 2 | BG1: Coluna Auxiliar Data 3 | BH1: Coluna Auxiliar Data 4
A2: 45658 | B2: =-SUMIFS(df_extrato_zig!G:G,df_extrato_zig!E:E,Conciliacao!A2,df_extrato_zig!D:D,"Saque")-SUMIFS(df_extrato_zig!G:G,df_extrato_zig!E:E,Conciliacao!A2,df_extrato_zig!D:D,"Antecipação") | C2: =SUMIFS(df_extrato_zig!E:E,df_extrato_zig!L:L,Conciliacao!A2,df_extrato_zig!F:F,"DINHEIRO") | D2: =SUMIFS(view_parc_agrup!H:H,view_parc_agrup!G:G,Conciliacao!A2) | E2: =SUMIFS(df_eventos!F:F,df_eventos!H:H,Conciliacao!A2) | F2: =SUMIFS(df_mutuos!M:M,df_mutuos!B:B,Conciliacao!A2) | G2: =SUMIFS(df_bloqueios_judiciais!G:G,df_bloqueios_judiciais!D:D,Conciliacao!A2,df_bloqueios_judiciais!G:G,">0") | H2: =SUMIFS(df_extratos!I:I,df_extratos!F:F,">="&Conciliacao!BE2,df_extratos!F:F,"<"&Conciliacao!BE2+1,df_extratos!G:G,"CREDITO") +SUMIFS(df_extratos!I:I,df_extratos!F:F,">="&Conciliacao!A2, df_extratos!F:F,"<"&Conciliacao!A2+1, df_extratos!G:G,"CREDITO") +SUMIFS(df_extratos!I:I,df_extratos!F:F,">="&Conciliacao!BF2,df_extratos!F:F,"<"&Conciliacao!BF2+1,df_extratos!G:G,"CREDITO") +SUMIFS(df_extratos!I:I,df_extratos!F:F,">="&Conciliacao!BG2,df_extratos!F:F,"<"&Conciliacao!BG2+1,df_extratos!G:G,"CREDITO") +SUMIFS(df_extratos!I:I,df_extratos!F:F,">="&Conciliacao!BH2,df_extratos!F:F,"<"&Conciliacao!BH2+1,df_extratos!G:G,"CREDITO") | I2: =H2-SUM(B2:G2) | J2: =SUMIFS(df_blueme_sem_parcelamento!E:E,df_blueme_sem_parcelamento!H:H,Conciliacao!A2)*(-1) | K2: =SUMIFS(df_blueme_com_parcelamento!J:J,df_blueme_com_parcelamento!M:M,Conciliacao!A2)*(-1) | L2: =SUMIFS(df_mutuos!N:N,df_mutuos!B:B,Conciliacao!A2)*(-1) | M2: =SUMIFS(df_bloqueios_judiciais!E:E,df_bloqueios_judiciais!D:D,Conciliacao!A2,df_bloqueios_judiciais!E:E,"<0") | N2: =SUMIFS(df_extratos!I:I,df_extratos!F:F,">="&Conciliacao!BE2,df_extratos!F:F,"<"&Conciliacao!BE2+1,df_extratos!G:G,"DEBITO") +SUMIFS(df_extratos!I:I,df_extratos!F:F,">="&Conciliacao!A2, df_extratos!F:F,"<"&Conciliacao!A2+1, df_extratos!G:G,"DEBITO") +SUMIFS(df_extratos!I:I,df_extratos!F:F,">="&Conciliacao!BF2,df_extratos!F:F,"<"&Conciliacao!BF2+1,df_extratos!G:G,"DEBITO") +SUMIFS(df_extratos!I:I,df_extratos!F:F,">="&Conciliacao!BG2,df_extratos!F:F,"<"&Conciliacao!BG2+1,df_extratos!G:G,"DEBITO") +SUMIFS(df_extratos!I:I,df_extratos!F:F,">="&Conciliacao!BH2,df_extratos!F:F,"<"&Conciliacao!BH2+1,df_extratos!G:G,"DEBITO") | O2: =N2-SUM(J2:M2) | P2: =SUMIFS(df_ajustes_conciliaco!D:D,df_ajustes_conciliaco!C:C,Conciliacao!A2) | Q2: =O2+I2-P2 | BE2: 45658.5 | BF2: 45658.125 | BG2: 45658.542 | BH2: 45658.625
A3: =A2+1 | B3: =-SUMIFS(df_extrato_zig!G:G,df_extrato_zig!E:E,Conciliacao!A3,df_extrato_zig!D:D,"Saque")-SUMIFS(df_extrato_zig!G:G,df_extrato_zig!E:E,Conciliacao!A3,df_extrato_zig!D:D,"Antecipação") | C3: =SUMIFS(df_extrato_zig!E:E,df_extrato_zig!L:L,Conciliacao!A3,df_extrato_zig!F:F,"DINHEIRO") | D3: =SUMIFS(view_parc_agrup!H:H,view_parc_agrup!G:G,Conciliacao!A3) | E3: =SUMIFS(df_eventos!F:F,df_eventos!H:H,Conciliacao!A3) | F3: =SUMIFS(df_mutuos!M:M,df_mutuos!B:B,Conciliacao!A3) | G3: =SUMIFS(df_bloqueios_judiciais!G:G,df_bloqueios_judiciais!D:D,Conciliacao!A3,df_bloqueios_judiciais!G:G,">0") | H3: =SUMIFS(df_extratos!I:I,df_extratos!F:F,">="&Conciliacao!BE3,df_extratos!F:F,"<"&Conciliacao!BE3+1,df_extratos!G:G,"CREDITO") +SUMIFS(df_extratos!I:I,df_extratos!F:F,">="&Conciliacao!A3, df_extratos!F:F,"<"&Conciliacao!A3+1, df_extratos!G:G,"CREDITO") +SUMIFS(df_extratos!I:I,df_extratos!F:F,">="&Conciliacao!BF3,df_extratos!F:F,"<"&Conciliacao!BF3+1,df_extratos!G:G,"CREDITO") +SUMIFS(df_extratos!I:I,df_extratos!F:F,">="&Conciliacao!BG3,df_extratos!F:F,"<"&Conciliacao!BG3+1,df_extratos!G:G,"CREDITO") +SUMIFS(df_extratos!I:I,df_extratos!F:F,">="&Conciliacao!BH3,df_extratos!F:F,"<"&Conciliacao!BH3+1,df_extratos!G:G,"CREDITO") | I3: =H3-SUM(B3:G3) | J3: =SUMIFS(df_blueme_sem_parcelamento!E:E,df_blueme_sem_parcelamento!H:H,Conciliacao!A3)*(-1) | K3: =SUMIFS(df_blueme_com_parcelamento!J:J,df_blueme_com_parcelamento!M:M,Conciliacao!A3)*(-1) | L3: =SUMIFS(df_mutuos!N:N,df_mutuos!B:B,Conciliacao!A3)*(-1) | M3: =SUMIFS(df_bloqueios_judiciais!E:E,df_bloqueios_judiciais!D:D,Conciliacao!A3,df_bloqueios_judiciais!E:E,"<0") | N3: =SUMIFS(df_extratos!I:I,df_extratos!F:F,">="&Conciliacao!BE3,df_extratos!F:F,"<"&Conciliacao!BE3+1,df_extratos!G:G,"DEBITO") +SUMIFS(df_extratos!I:I,df_extratos!F:F,">="&Conciliacao!A3, df_extratos!F:F,"<"&Conciliacao!A3+1, df_extratos!G:G,"DEBITO") +SUMIFS(df_extratos!I:I,df_extratos!F:F,">="&Conciliacao!BF3,df_extratos!F:F,"<"&Conciliacao!BF3+1,df_extratos!G:G,"DEBITO") +SUMIFS(df_extratos!I:I,df_extratos!F:F,">="&Conciliacao!BG3,df_extratos!F:F,"<"&Conciliacao!BG3+1,df_extratos!G:G,"DEBITO") +SUMIFS(df_extratos!I:I,df_extratos!F:F,">="&Conciliacao!BH3,df_extratos!F:F,"<"&Conciliacao!BH3+1,df_extratos!G:G,"DEBITO") | O3: =N3-SUM(J3:M3) | P3: =SUMIFS(df_ajustes_conciliaco!D:D,df_ajustes_conciliaco!C:C,Conciliacao!A3) | Q3: =O3+I3-P3 | BE3: 45659.5 | BF3: 45659.125 | BG3: 45659.542 | BH3: 45659.625
A4: =A3+1 | B4: =-SUMIFS(df_extrato_zig!G:G,df_extrato_zig!E:E,Conciliacao!A4,df_extrato_zig!D:D,"Saque")-SUMIFS(df_extrato_zig!G:G,df_extrato_zig!E:E,Conciliacao!A4,df_extrato_zig!D:D,"Antecipação") | C4: =SUMIFS(df_extrato_zig!E:E,df_extrato_zig!L:L,Conciliacao!A4,df_extrato_zig!F:F,"DINHEIRO") | D4: =SUMIFS(view_parc_agrup!H:H,view_parc_agrup!G:G,Conciliacao!A4) | E4: =SUMIFS(df_eventos!F:F,df_eventos!H:H,Conciliacao!A4) | F4: =SUMIFS(df_mutuos!M:M,df_mutuos!B:B,Conciliacao!A4) | G4: =SUMIFS(df_bloqueios_judiciais!G:G,df_bloqueios_judiciais!D:D,Conciliacao!A4,df_bloqueios_judiciais!G:G,">0") | H4: =SUMIFS(df_extratos!I:I,df_extratos!F:F,">="&Conciliacao!BE4,df_extratos!F:F,"<"&Conciliacao!BE4+1,df_extratos!G:G,"CREDITO") +SUMIFS(df_extratos!I:I,df_extratos!F:F,">="&Conciliacao!A4, df_extratos!F:F,"<"&Conciliacao!A4+1, df_extratos!G:G,"CREDITO") +SUMIFS(df_extratos!I:I,df_extratos!F:F,">="&Conciliacao!BF4,df_extratos!F:F,"<"&Conciliacao!BF4+1,df_extratos!G:G,"CREDITO") +SUMIFS(df_extratos!I:I,df_extratos!F:F,">="&Conciliacao!BG4,df_extratos!F:F,"<"&Conciliacao!BG4+1,df_extratos!G:G,"CREDITO") +SUMIFS(df_extratos!I:I,df_extratos!F:F,">="&Conciliacao!BH4,df_extratos!F:F,"<"&Conciliacao!BH4+1,df_extratos!G:G,"CREDITO") | I4: =H4-SUM(B4:G4) | J4: =SUMIFS(df_blueme_sem_parcelamento!E:E,df_blueme_sem_parcelamento!H:H,Conciliacao!A4)*(-1) | K4: =SUMIFS(df_blueme_com_parcelamento!J:J,df_blueme_com_parcelamento!M:M,Conciliacao!A4)*(-1) | L4: =SUMIFS(df_mutuos!N:N,df_mutuos!B:B,Conciliacao!A4)*(-1) | M4: =SUMIFS(df_bloqueios_judiciais!E:E,df_bloqueios_judiciais!D:D,Conciliacao!A4,df_bloqueios_judiciais!E:E,"<0") | N4: =SUMIFS(df_extratos!I:I,df_extratos!F:F,">="&Conciliacao!BE4,df_extratos!F:F,"<"&Conciliacao!BE4+1,df_extratos!G:G,"DEBITO") +SUMIFS(df_extratos!I:I,df_extratos!F:F,">="&Conciliacao!A4, df_extratos!F:F,"<"&Conciliacao!A4+1, df_extratos!G:G,"DEBITO") +SUMIFS(df_extratos!I:I,df_extratos!F:F,">="&Conciliacao!BF4,df_extratos!F:F,"<"&Conciliacao!BF4+1,df_extratos!G:G,"DEBITO") +SUMIFS(df_extratos!I:I,df_extratos!F:F,">="&Conciliacao!BG4,df_extratos!F:F,"<"&Conciliacao!BG4+1,df_extratos!G:G,"DEBITO") +SUMIFS(df_extratos!I:I,df_extratos!F:F,">="&Conciliacao!BH4,df_extratos!F:F,"<"&Conciliacao!BH4+1,df_extratos!G:G,"DEBITO") | O4: =N4-SUM(J4:M4) | P4: =SUMIFS(df_ajustes_conciliaco!D:D,df_ajustes_conciliaco!C:C,Conciliacao!A4) | Q4: =O4+I4-P4 | BE4: 45660.5 | BF4: 45660.125 | BG4: 45660.542 | BH4: 45660.625
A5: =A4+1 | B5: =-SUMIFS(df_extrato_zig!G:G,df_extrato_zig!E:E,Conciliacao!A5,df_extrato_zig!D:D,"Saque")-SUMIFS(df_extrato_zig!G:G,df_extrato_zig!E:E,Conciliacao!A5,df_extrato_zig!D:D,"Antecipação") | C5: =SUMIFS(df_extrato_zig!E:E,df_extrato_zig!L:L,Conciliacao!A5,df_extrato_zig!F:F,"DINHEIRO") | D5: =SUMIFS(view_parc_agrup!H:H,view_parc_agrup!G:G,Conciliacao!A5) | E5: =SUMIFS(df_eventos!F:F,df_eventos!H:H,Conciliacao!A5) | F5: =SUMIFS(df_mutuos!M:M,df_mutuos!B:B,Conciliacao!A5) | G5: =SUMIFS(df_bloqueios_judiciais!G:G,df_bloqueios_judiciais!D:D,Conciliacao!A5,df_bloqueios_judiciais!G:G,">0") | H5: =SUMIFS(df_extratos!I:I,df_extratos!F:F,">="&Conciliacao!BE5,df_extratos!F:F,"<"&Conciliacao!BE5+1,df_extratos!G:G,"CREDITO") +SUMIFS(df_extratos!I:I,df_extratos!F:F,">="&Conciliacao!A5, df_extratos!F:F,"<"&Conciliacao!A5+1, df_extratos!G:G,"CREDITO") +SUMIFS(df_extratos!I:I,df_extratos!F:F,">="&Conciliacao!BF5,df_extratos!F:F,"<"&Conciliacao!BF5+1,df_extratos!G:G,"CREDITO") +SUMIFS(df_extratos!I:I,df_extratos!F:F,">="&Conciliacao!BG5,df_extratos!F:F,"<"&Conciliacao!BG5+1,df_extratos!G:G,"CREDITO") +SUMIFS(df_extratos!I:I,df_extratos!F:F,">="&Conciliacao!BH5,df_extratos!F:F,"<"&Conciliacao!BH5+1,df_extratos!G:G,"CREDITO") | I5: =H5-SUM(B5:G5) | J5: =SUMIFS(df_blueme_sem_parcelamento!E:E,df_blueme_sem_parcelamento!H:H,Conciliacao!A5)*(-1) | K5: =SUMIFS(df_blueme_com_parcelamento!J:J,df_blueme_com_parcelamento!M:M,Conciliacao!A5)*(-1) | L5: =SUMIFS(df_mutuos!N:N,df_mutuos!B:B,Conciliacao!A5)*(-1) | M5: =SUMIFS(df_bloqueios_judiciais!E:E,df_bloqueios_judiciais!D:D,Conciliacao!A5,df_bloqueios_judiciais!E:E,"<0") | N5: =SUMIFS(df_extratos!I:I,df_extratos!F:F,">="&Conciliacao!BE5,df_extratos!F:F,"<"&Conciliacao!BE5+1,df_extratos!G:G,"DEBITO") +SUMIFS(df_extratos!I:I,df_extratos!F:F,">="&Conciliacao!A5, df_extratos!F:F,"<"&Conciliacao!A5+1, df_extratos!G:G,"DEBITO") +SUMIFS(df_extratos!I:I,df_extratos!F:F,">="&Conciliacao!BF5,df_extratos!F:F,"<"&Conciliacao!BF5+1,df_extratos!G:G,"DEBITO") +SUMIFS(df_extratos!I:I,df_extratos!F:F,">="&Conciliacao!BG5,df_extratos!F:F,"<"&Conciliacao!BG5+1,df_extratos!G:G,"DEBITO") +SUMIFS(df_extratos!I:I,df_extratos!F:F,">="&Conciliacao!BH5,df_extratos!F:F,"<"&Conciliacao!BH5+1,df_extratos!G:G,"DEBITO") | O5: =N5-SUM(J5:M5) | P5: =SUMIFS(df_ajustes_conciliaco!D:D,df_ajustes_conciliaco!C:C,Conciliacao!A5) | Q5: =O5+I5-P5 | BE5: 45661.5 | BF5: 45661.125 | BG5: 45661.542 | BH5: 45661.625
A6: =A5+1 | B6: =-SUMIFS(df_extrato_zig!G:G,df_extrato_zig!E:E,Conciliacao!A6,df_extrato_zig!D:D,"Saque")-SUMIFS(df_extrato_zig!G:G,df_extrato_zig!E:E,Conciliacao!A6,df_extrato_zig!D:D,"Antecipação") | C6: =SUMIFS(df_extrato_zig!E:E,df_extrato_zig!L:L,Conciliacao!A6,df_extrato_zig!F:F,"DINHEIRO") | D6: =SUMIFS(view_parc_agrup!H:H,view_parc_agrup!G:G,Conciliacao!A6) | E6: =SUMIFS(df_eventos!F:F,df_eventos!H:H,Conciliacao!A6) | F6: =SUMIFS(df_mutuos!M:M,df_mutuos!B:B,Conciliacao!A6) | G6: =SUMIFS(df_bloqueios_judiciais!G:G,df_bloqueios_judiciais!D:D,Conciliacao!A6,df_bloqueios_judiciais!G:G,">0") | H6: =SUMIFS(df_extratos!I:I,df_extratos!F:F,">="&Conciliacao!BE6,df_extratos!F:F,"<"&Conciliacao!BE6+1,df_extratos!G:G,"CREDITO") +SUMIFS(df_extratos!I:I,df_extratos!F:F,">="&Conciliacao!A6, df_extratos!F:F,"<"&Conciliacao!A6+1, df_extratos!G:G,"CREDITO") +SUMIFS(df_extratos!I:I,df_extratos!F:F,">="&Conciliacao!BF6,df_extratos!F:F,"<"&Conciliacao!BF6+1,df_extratos!G:G,"CREDITO") +SUMIFS(df_extratos!I:I,df_extratos!F:F,">="&Conciliacao!BG6,df_extratos!F:F,"<"&Conciliacao!BG6+1,df_extratos!G:G,"CREDITO") +SUMIFS(df_extratos!I:I,df_extratos!F:F,">="&Conciliacao!BH6,df_extratos!F:F,"<"&Conciliacao!BH6+1,df_extratos!G:G,"CREDITO") | I6: =H6-SUM(B6:G6) | J6: =SUMIFS(df_blueme_sem_parcelamento!E:E,df_blueme_sem_parcelamento!H:H,Conciliacao!A6)*(-1) | K6: =SUMIFS(df_blueme_com_parcelamento!J:J,df_blueme_com_parcelamento!M:M,Conciliacao!A6)*(-1) | L6: =SUMIFS(df_mutuos!N:N,df_mutuos!B:B,Conciliacao!A6)*(-1) | M6: =SUMIFS(df_bloqueios_judiciais!E:E,df_bloqueios_judiciais!D:D,Conciliacao!A6,df_bloqueios_judiciais!E:E,"<0") | N6: =SUMIFS(df_extratos!I:I,df_extratos!F:F,">="&Conciliacao!BE6,df_extratos!F:F,"<"&Conciliacao!BE6+1,df_extratos!G:G,"DEBITO") +SUMIFS(df_extratos!I:I,df_extratos!F:F,">="&Conciliacao!A6, df_extratos!F:F,"<"&Conciliacao!A6+1, df_extratos!G:G,"DEBITO") +SUMIFS(df_extratos!I:I,df_extratos!F:F,">="&Conciliacao!BF6,df_extratos!F:F,"<"&Conciliacao!BF6+1,df_extratos!G:G,"DEBITO") +SUMIFS(df_extratos!I:I,df_extratos!F:F,">="&Conciliacao!BG6,df_extratos!F:F,"<"&Conciliacao!BG6+1,df_extratos!G:G,"DEBITO") +SUMIFS(df_extratos!I:I,df_extratos!F:F,">="&Conciliacao!BH6,df_extratos!F:F,"<"&Conciliacao!BH6+1,df_extratos!G:G,"DEBITO") | O6: =N6-SUM(J6:M6) | P6: =SUMIFS(df_ajustes_conciliaco!D:D,df_ajustes_conciliaco!C:C,Conciliacao!A6) | Q6: =O6+I6-P6 | BE6: 45662.5 | BF6: 45662.125 | BG6: 45662.542 | BH6: 45662.625
A7: =A6+1 | B7: =-SUMIFS(df_extrato_zig!G:G,df_extrato_zig!E:E,Conciliacao!A7,df_extrato_zig!D:D,"Saque")-SUMIFS(df_extrato_zig!G:G,df_extrato_zig!E:E,Conciliacao!A7,df_extrato_zig!D:D,"Antecipação") | C7: =SUMIFS(df_extrato_zig!E:E,df_extrato_zig!L:L,Conciliacao!A7,df_extrato_zig!F:F,"DINHEIRO") | D7: =SUMIFS(view_parc_agrup!H:H,view_parc_agrup!G:G,Conciliacao!A7) | E7: =SUMIFS(df_eventos!F:F,df_eventos!H:H,Conciliacao!A7) | F7: =SUMIFS(df_mutuos!M:M,df_mutuos!B:B,Conciliacao!A7) | G7: =SUMIFS(df_bloqueios_judiciais!G:G,df_bloqueios_judiciais!D:D,Conciliacao!A7,df_bloqueios_judiciais!G:G,">0") | H7: =SUMIFS(df_extratos!I:I,df_extratos!F:F,">="&Conciliacao!BE7,df_extratos!F:F,"<"&Conciliacao!BE7+1,df_extratos!G:G,"CREDITO") +SUMIFS(df_extratos!I:I,df_extratos!F:F,">="&Conciliacao!A7, df_extratos!F:F,"<"&Conciliacao!A7+1, df_extratos!G:G,"CREDITO") +SUMIFS(df_extratos!I:I,df_extratos!F:F,">="&Conciliacao!BF7,df_extratos!F:F,"<"&Conciliacao!BF7+1,df_extratos!G:G,"CREDITO") +SUMIFS(df_extratos!I:I,df_extratos!F:F,">="&Conciliacao!BG7,df_extratos!F:F,"<"&Conciliacao!BG7+1,df_extratos!G:G,"CREDITO") +SUMIFS(df_extratos!I:I,df_extratos!F:F,">="&Conciliacao!BH7,df_extratos!F:F,"<"&Conciliacao!BH7+1,df_extratos!G:G,"CREDITO") | I7: =H7-SUM(B7:G7) | J7: =SUMIFS(df_blueme_sem_parcelamento!E:E,df_blueme_sem_parcelamento!H:H,Conciliacao!A7)*(-1) | K7: =SUMIFS(df_blueme_com_parcelamento!J:J,df_blueme_com_parcelamento!M:M,Conciliacao!A7)*(-1) | L7: =SUMIFS(df_mutuos!N:N,df_mutuos!B:B,Conciliacao!A7)*(-1) | M7: =SUMIFS(df_bloqueios_judiciais!E:E,df_bloqueios_judiciais!D:D,Conciliacao!A7,df_bloqueios_judiciais!E:E,"<0") | N7: =SUMIFS(df_extratos!I:I,df_extratos!F:F,">="&Conciliacao!BE7,df_extratos!F:F,"<"&Conciliacao!BE7+1,df_extratos!G:G,"DEBITO") +SUMIFS(df_extratos!I:I,df_extratos!F:F,">="&Conciliacao!A7, df_extratos!F:F,"<"&Conciliacao!A7+1, df_extratos!G:G,"DEBITO") +SUMIFS(df_extratos!I:I,df_extratos!F:F,">="&Conciliacao!BF7,df_extratos!F:F,"<"&Conciliacao!BF7+1,df_extratos!G:G,"DEBITO") +SUMIFS(df_extratos!I:I,df_extratos!F:F,">="&Conciliacao!BG7,df_extratos!F:F,"<"&Conciliacao!BG7+1,df_extratos!G:G,"DEBITO") +SUMIFS(df_extratos!I:I,df_extratos!F:F,">="&Conciliacao!BH7,df_extratos!F:F,"<"&Conciliacao!BH7+1,df_extratos!G:G,"DEBITO") | O7: =N7-SUM(J7:M7) | P7: =SUMIFS(df_ajustes_conciliaco!D:D,df_ajustes_conciliaco!C:C,Conciliacao!A7) | Q7: =O7+I7-P7 | BE7: 45663.5 | BF7: 45663.125 | BG7: 45663.542 | BH7: 45663.625
A8: =A7+1 | B8: =-SUMIFS(df_extrato_zig!G:G,df_extrato_zig!E:E,Conciliacao!A8,df_extrato_zig!D:D,"Saque")-SUMIFS(df_extrato_zig!G:G,df_extrato_zig!E:E,Conciliacao!A8,df_extrato_zig!D:D,"Antecipação") | C8: =SUMIFS(df_extrato_zig!E:E,df_extrato_zig!L:L,Conciliacao!A8,df_extrato_zig!F:F,"DINHEIRO") | D8: =SUMIFS(view_parc_agrup!H:H,view_parc_agrup!G:G,Conciliacao!A8) | E8: =SUMIFS(df_eventos!F:F,df_eventos!H:H,Conciliacao!A8) | F8: =SUMIFS(df_mutuos!M:M,df_mutuos!B:B,Conciliacao!A8) | G8: =SUMIFS(df_bloqueios_judiciais!G:G,df_bloqueios_judiciais!D:D,Conciliacao!A8,df_bloqueios_judiciais!G:G,">0") | H8: =SUMIFS(df_extratos!I:I,df_extratos!F:F,">="&Conciliacao!BE8,df_extratos!F:F,"<"&Conciliacao!BE8+1,df_extratos!G:G,"CREDITO") +SUMIFS(df_extratos!I:I,df_extratos!F:F,">="&Conciliacao!A8, df_extratos!F:F,"<"&Conciliacao!A8+1, df_extratos!G:G,"CREDITO") +SUMIFS(df_extratos!I:I,df_extratos!F:F,">="&Conciliacao!BF8,df_extratos!F:F,"<"&Conciliacao!BF8+1,df_extratos!G:G,"CREDITO") +SUMIFS(df_extratos!I:I,df_extratos!F:F,">="&Conciliacao!BG8,df_extratos!F:F,"<"&Conciliacao!BG8+1,df_extratos!G:G,"CREDITO") +SUMIFS(df_extratos!I:I,df_extratos!F:F,">="&Conciliacao!BH8,df_extratos!F:F,"<"&Conciliacao!BH8+1,df_extratos!G:G,"CREDITO") | I8: =H8-SUM(B8:G8) | J8: =SUMIFS(df_blueme_sem_parcelamento!E:E,df_blueme_sem_parcelamento!H:H,Conciliacao!A8)*(-1) | K8: =SUMIFS(df_blueme_com_parcelamento!J:J,df_blueme_com_parcelamento!M:M,Conciliacao!A8)*(-1) | L8: =SUMIFS(df_mutuos!N:N,df_mutuos!B:B,Conciliacao!A8)*(-1) | M8: =SUMIFS(df_bloqueios_judiciais!E:E,df_bloqueios_judiciais!D:D,Conciliacao!A8,df_bloqueios_judiciais!E:E,"<0") | N8: =SUMIFS(df_extratos!I:I,df_extratos!F:F,">="&Conciliacao!BE8,df_extratos!F:F,"<"&Conciliacao!BE8+1,df_extratos!G:G,"DEBITO") +SUMIFS(df_extratos!I:I,df_extratos!F:F,">="&Conciliacao!A8, df_extratos!F:F,"<"&Conciliacao!A8+1, df_extratos!G:G,"DEBITO") +SUMIFS(df_extratos!I:I,df_extratos!F:F,">="&Conciliacao!BF8,df_extratos!F:F,"<"&Conciliacao!BF8+1,df_extratos!G:G,"DEBITO") +SUMIFS(df_extratos!I:I,df_extratos!F:F,">="&Conciliacao!BG8,df_extratos!F:F,"<"&Conciliacao!BG8+1,df_extratos!G:G,"DEBITO") +SUMIFS(df_extratos!I:I,df_extratos!F:F,">="&Conciliacao!BH8,df_extratos!F:F,"<"&Conciliacao!BH8+1,df_extratos!G:G,"DEBITO") | O8: =N8-SUM(J8:M8) | P8: =SUMIFS(df_ajustes_conciliaco!D:D,df_ajustes_conciliaco!C:C,Conciliacao!A8) | Q8: =O8+I8-P8 | BE8: 45664.5 | BF8: 45664.125 | BG8: 45664.542 | BH8: 45664.625
A9: =A8+1 | B9: =-SUMIFS(df_extrato_zig!G:G,df_extrato_zig!E:E,Conciliacao!A9,df_extrato_zig!D:D,"Saque")-SUMIFS(df_extrato_zig!G:G,df_extrato_zig!E:E,Conciliacao!A9,df_extrato_zig!D:D,"Antecipação") | C9: =SUMIFS(df_extrato_zig!E:E,df_extrato_zig!L:L,Conciliacao!A9,df_extrato_zig!F:F,"DINHEIRO") | D9: =SUMIFS(view_parc_agrup!H:H,view_parc_agrup!G:G,Conciliacao!A9) | E9: =SUMIFS(df_eventos!F:F,df_eventos!H:H,Conciliacao!A9) | F9: =SUMIFS(df_mutuos!M:M,df_mutuos!B:B,Conciliacao!A9) | G9: =SUMIFS(df_bloqueios_judiciais!G:G,df_bloqueios_judiciais!D:D,Conciliacao!A9,df_bloqueios_judiciais!G:G,">0") | H9: =SUMIFS(df_extratos!I:I,df_extratos!F:F,">="&Conciliacao!BE9,df_extratos!F:F,"<"&Conciliacao!BE9+1,df_extratos!G:G,"CREDITO") +SUMIFS(df_extratos!I:I,df_extratos!F:F,">="&Conciliacao!A9, df_extratos!F:F,"<"&Conciliacao!A9+1, df_extratos!G:G,"CREDITO") +SUMIFS(df_extratos!I:I,df_extratos!F:F,">="&Conciliacao!BF9,df_extratos!F:F,"<"&Conciliacao!BF9+1,df_extratos!G:G,"CREDITO") +SUMIFS(df_extratos!I:I,df_extratos!F:F,">="&Conciliacao!BG9,df_extratos!F:F,"<"&Conciliacao!BG9+1,df_extratos!G:G,"CREDITO") +SUMIFS(df_extratos!I:I,df_extratos!F:F,">="&Conciliacao!BH9,df_extratos!F:F,"<"&Conciliacao!BH9+1,df_extratos!G:G,"CREDITO") | I9: =H9-SUM(B9:G9) | J9: =SUMIFS(df_blueme_sem_parcelamento!E:E,df_blueme_sem_parcelamento!H:H,Conciliacao!A9)*(-1) | K9: =SUMIFS(df_blueme_com_parcelamento!J:J,df_blueme_com_parcelamento!M:M,Conciliacao!A9)*(-1) | L9: =SUMIFS(df_mutuos!N:N,df_mutuos!B:B,Conciliacao!A9)*(-1) | M9: =SUMIFS(df_bloqueios_judiciais!E:E,df_bloqueios_judiciais!D:D,Conciliacao!A9,df_bloqueios_judiciais!E:E,"<0") | N9: =SUMIFS(df_extratos!I:I,df_extratos!F:F,">="&Conciliacao!BE9,df_extratos!F:F,"<"&Conciliacao!BE9+1,df_extratos!G:G,"DEBITO") +SUMIFS(df_extratos!I:I,df_extratos!F:F,">="&Conciliacao!A9, df_extratos!F:F,"<"&Conciliacao!A9+1, df_extratos!G:G,"DEBITO") +SUMIFS(df_extratos!I:I,df_extratos!F:F,">="&Conciliacao!BF9,df_extratos!F:F,"<"&Conciliacao!BF9+1,df_extratos!G:G,"DEBITO") +SUMIFS(df_extratos!I:I,df_extratos!F:F,">="&Conciliacao!BG9,df_extratos!F:F,"<"&Conciliacao!BG9+1,df_extratos!G:G,"DEBITO") +SUMIFS(df_extratos!I:I,df_extratos!F:F,">="&Conciliacao!BH9,df_extratos!F:F,"<"&Conciliacao!BH9+1,df_extratos!G:G,"DEBITO") | O9: =N9-SUM(J9:M9) | P9: =SUMIFS(df_ajustes_conciliaco!D:D,df_ajustes_conciliaco!C:C,Conciliacao!A9) | Q9: =O9+I9-P9 | BE9: 45665.5 | BF9: 45665.125 | BG9: 45665.542 | BH9: 45665.625
A10: =A9+1 | B10: =-SUMIFS(df_extrato_zig!G:G,df_extrato_zig!E:E,Conciliacao!A10,df_extrato_zig!D:D,"Saque")-SUMIFS(df_extrato_zig!G:G,df_extrato_zig!E:E,Conciliacao!A10,df_extrato_zig!D:D,"Antecipação") | C10: =SUMIFS(df_extrato_zig!E:E,df_extrato_zig!L:L,Conciliacao!A10,df_extrato_zig!F:F,"DINHEIRO") | D10: =SUMIFS(view_parc_agrup!H:H,view_parc_agrup!G:G,Conciliacao!A10) | E10: =SUMIFS(df_eventos!F:F,df_eventos!H:H,Conciliacao!A10) | F10: =SUMIFS(df_mutuos!M:M,df_mutuos!B:B,Conciliacao!A10) | G10: =SUMIFS(df_bloqueios_judiciais!G:G,df_bloqueios_judiciais!D:D,Conciliacao!A10,df_bloqueios_judiciais!G:G,">0") | H10: =SUMIFS(df_extratos!I:I,df_extratos!F:F,">="&Conciliacao!BE10,df_extratos!F:F,"<"&Conciliacao!BE10+1,df_extratos!G:G,"CREDITO") +SUMIFS(df_extratos!I:I,df_extratos!F:F,">="&Conciliacao!A10, df_extratos!F:F,"<"&Conciliacao!A10+1, df_extratos!G:G,"CREDITO") +SUMIFS(df_extratos!I:I,df_extratos!F:F,">="&Conciliacao!BF10,df_extratos!F:F,"<"&Conciliacao!BF10+1,df_extratos!G:G,"CREDITO") +SUMIFS(df_extratos!I:I,df_extratos!F:F,">="&Conciliacao!BG10,df_extratos!F:F,"<"&Conciliacao!BG10+1,df_extratos!G:G,"CREDITO") +SUMIFS(df_extratos!I:I,df_extratos!F:F,">="&Conciliacao!BH10,df_extratos!F:F,"<"&Conciliacao!BH10+1,df_extratos!G:G,"CREDITO") | I10: =H10-SUM(B10:G10) | J10: =SUMIFS(df_blueme_sem_parcelamento!E:E,df_blueme_sem_parcelamento!H:H,Conciliacao!A10)*(-1) | K10: =SUMIFS(df_blueme_com_parcelamento!J:J,df_blueme_com_parcelamento!M:M,Conciliacao!A10)*(-1) | L10: =SUMIFS(df_mutuos!N:N,df_mutuos!B:B,Conciliacao!A10)*(-1) | M10: =SUMIFS(df_bloqueios_judiciais!E:E,df_bloqueios_judiciais!D:D,Conciliacao!A10,df_bloqueios_judiciais!E:E,"<0") | N10: =SUMIFS(df_extratos!I:I,df_extratos!F:F,">="&Conciliacao!BE10,df_extratos!F:F,"<"&Conciliacao!BE10+1,df_extratos!G:G,"DEBITO") +SUMIFS(df_extratos!I:I,df_extratos!F:F,">="&Conciliacao!A10, df_extratos!F:F,"<"&Conciliacao!A10+1, df_extratos!G:G,"DEBITO") +SUMIFS(df_extratos!I:I,df_extratos!F:F,">="&Conciliacao!BF10,df_extratos!F:F,"<"&Conciliacao!BF10+1,df_extratos!G:G,"DEBITO") +SUMIFS(df_extratos!I:I,df_extratos!F:F,">="&Conciliacao!BG10,df_extratos!F:F,"<"&Conciliacao!BG10+1,df_extratos!G:G,"DEBITO") +SUMIFS(df_extratos!I:I,df_extratos!F:F,">="&Conciliacao!BH10,df_extratos!F:F,"<"&Conciliacao!BH10+1,df_extratos!G:G,"DEBITO") | O10: =N10-SUM(J10:M10) | P10: =SUMIFS(df_ajustes_conciliaco!D:D,df_ajustes_conciliaco!C:C,Conciliacao!A10) | Q10: =O10+I10-P10 | BE10: 45666.5 | BF10: 45666.125 | BG10: 45666.542 | BH10: 45666.625
A11: =A10+1 | B11: =-SUMIFS(df_extrato_zig!G:G,df_extrato_zig!E:E,Conciliacao!A11,df_extrato_zig!D:D,"Saque")-SUMIFS(df_extrato_zig!G:G,df_extrato_zig!E:E,Conciliacao!A11,df_extrato_zig!D:D,"Antecipação") | C11: =SUMIFS(df_extrato_zig!E:E,df_extrato_zig!L:L,Conciliacao!A11,df_extrato_zig!F:F,"DINHEIRO") | D11: =SUMIFS(view_parc_agrup!H:H,view_parc_agrup!G:G,Conciliacao!A11) | E11: =SUMIFS(df_eventos!F:F,df_eventos!H:H,Conciliacao!A11) | F11: =SUMIFS(df_mutuos!M:M,df_mutuos!B:B,Conciliacao!A11) | G11: =SUMIFS(df_bloqueios_judiciais!G:G,df_bloqueios_judiciais!D:D,Conciliacao!A11,df_bloqueios_judiciais!G:G,">0") | H11: =SUMIFS(df_extratos!I:I,df_extratos!F:F,">="&Conciliacao!BE11,df_extratos!F:F,"<"&Conciliacao!BE11+1,df_extratos!G:G,"CREDITO") +SUMIFS(df_extratos!I:I,df_extratos!F:F,">="&Conciliacao!A11, df_extratos!F:F,"<"&Conciliacao!A11+1, df_extratos!G:G,"CREDITO") +SUMIFS(df_extratos!I:I,df_extratos!F:F,">="&Conciliacao!BF11,df_extratos!F:F,"<"&Conciliacao!BF11+1,df_extratos!G:G,"CREDITO") +SUMIFS(df_extratos!I:I,df_extratos!F:F,">="&Conciliacao!BG11,df_extratos!F:F,"<"&Conciliacao!BG11+1,df_extratos!G:G,"CREDITO") +SUMIFS(df_extratos!I:I,df_extratos!F:F,">="&Conciliacao!BH11,df_extratos!F:F,"<"&Conciliacao!BH11+1,df_extratos!G:G,"CREDITO") | I11: =H11-SUM(B11:G11) | J11: =SUMIFS(df_blueme_sem_parcelamento!E:E,df_blueme_sem_parcelamento!H:H,Conciliacao!A11)*(-1) | K11: =SUMIFS(df_blueme_com_parcelamento!J:J,df_blueme_com_parcelamento!M:M,Conciliacao!A11)*(-1) | L11: =SUMIFS(df_mutuos!N:N,df_mutuos!B:B,Conciliacao!A11)*(-1) | M11: =SUMIFS(df_bloqueios_judiciais!E:E,df_bloqueios_judiciais!D:D,Conciliacao!A11,df_bloqueios_judiciais!E:E,"<0") | N11: =SUMIFS(df_extratos!I:I,df_extratos!F:F,">="&Conciliacao!BE11,df_extratos!F:F,"<"&Conciliacao!BE11+1,df_extratos!G:G,"DEBITO") +SUMIFS(df_extratos!I:I,df_extratos!F:F,">="&Conciliacao!A11, df_extratos!F:F,"<"&Conciliacao!A11+1, df_extratos!G:G,"DEBITO") +SUMIFS(df_extratos!I:I,df_extratos!F:F,">="&Conciliacao!BF11,df_extratos!F:F,"<"&Conciliacao!BF11+1,df_extratos!G:G,"DEBITO") +SUMIFS(df_extratos!I:I,df_extratos!F:F,">="&Conciliacao!BG11,df_extratos!F:F,"<"&Conciliacao!BG11+1,df_extratos!G:G,"DEBITO") +SUMIFS(df_extratos!I:I,df_extratos!F:F,">="&Conciliacao!BH11,df_extratos!F:F,"<"&Conciliacao!BH11+1,df_extratos!G:G,"DEBITO") | O11: =N11-SUM(J11:M11) | P11: =SUMIFS(df_ajustes_conciliaco!D:D,df_ajustes_conciliaco!C:C,Conciliacao!A11) | Q11: =O11+I11-P11 | BE11: 45667.5 | BF11: 45667.125 | BG11: 45667.542 | BH11: 45667.625
A12: =A11+1 | B12: =-SUMIFS(df_extrato_zig!G:G,df_extrato_zig!E:E,Conciliacao!A12,df_extrato_zig!D:D,"Saque")-SUMIFS(df_extrato_zig!G:G,df_extrato_zig!E:E,Conciliacao!A12,df_extrato_zig!D:D,"Antecipação") | C12: =SUMIFS(df_extrato_zig!E:E,df_extrato_zig!L:L,Conciliacao!A12,df_extrato_zig!F:F,"DINHEIRO") | D12: =SUMIFS(view_parc_agrup!H:H,view_parc_agrup!G:G,Conciliacao!A12) | E12: =SUMIFS(df_eventos!F:F,df_eventos!H:H,Conciliacao!A12) | F12: =SUMIFS(df_mutuos!M:M,df_mutuos!B:B,Conciliacao!A12) | G12: =SUMIFS(df_bloqueios_judiciais!G:G,df_bloqueios_judiciais!D:D,Conciliacao!A12,df_bloqueios_judiciais!G:G,">0") | H12: =SUMIFS(df_extratos!I:I,df_extratos!F:F,">="&Conciliacao!BE12,df_extratos!F:F,"<"&Conciliacao!BE12+1,df_extratos!G:G,"CREDITO") +SUMIFS(df_extratos!I:I,df_extratos!F:F,">="&Conciliacao!A12, df_extratos!F:F,"<"&Conciliacao!A12+1, df_extratos!G:G,"CREDITO") +SUMIFS(df_extratos!I:I,df_extratos!F:F,">="&Conciliacao!BF12,df_extratos!F:F,"<"&Conciliacao!BF12+1,df_extratos!G:G,"CREDITO") +SUMIFS(df_extratos!I:I,df_extratos!F:F,">="&Conciliacao!BG12,df_extratos!F:F,"<"&Conciliacao!BG12+1,df_extratos!G:G,"CREDITO") +SUMIFS(df_extratos!I:I,df_extratos!F:F,">="&Conciliacao!BH12,df_extratos!F:F,"<"&Conciliacao!BH12+1,df_extratos!G:G,"CREDITO") | I12: =H12-SUM(B12:G12) | J12: =SUMIFS(df_blueme_sem_parcelamento!E:E,df_blueme_sem_parcelamento!H:H,Conciliacao!A12)*(-1) | K12: =SUMIFS(df_blueme_com_parcelamento!J:J,df_blueme_com_parcelamento!M:M,Conciliacao!A12)*(-1) | L12: =SUMIFS(df_mutuos!N:N,df_mutuos!B:B,Conciliacao!A12)*(-1) | M12: =SUMIFS(df_bloqueios_judiciais!E:E,df_bloqueios_judiciais!D:D,Conciliacao!A12,df_bloqueios_judiciais!E:E,"<0") | N12: =SUMIFS(df_extratos!I:I,df_extratos!F:F,">="&Conciliacao!BE12,df_extratos!F:F,"<"&Conciliacao!BE12+1,df_extratos!G:G,"DEBITO") +SUMIFS(df_extratos!I:I,df_extratos!F:F,">="&Conciliacao!A12, df_extratos!F:F,"<"&Conciliacao!A12+1, df_extratos!G:G,"DEBITO") +SUMIFS(df_extratos!I:I,df_extratos!F:F,">="&Conciliacao!BF12,df_extratos!F:F,"<"&Conciliacao!BF12+1,df_extratos!G:G,"DEBITO") +SUMIFS(df_extratos!I:I,df_extratos!F:F,">="&Conciliacao!BG12,df_extratos!F:F,"<"&Conciliacao!BG12+1,df_extratos!G:G,"DEBITO") +SUMIFS(df_extratos!I:I,df_extratos!F:F,">="&Conciliacao!BH12,df_extratos!F:F,"<"&Conciliacao!BH12+1,df_extratos!G:G,"DEBITO") | O12: =N12-SUM(J12:M12) | P12: =SUMIFS(df_ajustes_conciliaco!D:D,df_ajustes_conciliaco!C:C,Conciliacao!A12) | Q12: =O12+I12-P12 | BE12: 45668.5 | BF12: 45668.125 | BG12: 45668.542 | BH12: 45668.625
A13: =A12+1 | B13: =-SUMIFS(df_extrato_zig!G:G,df_extrato_zig!E:E,Conciliacao!A13,df_extrato_zig!D:D,"Saque")-SUMIFS(df_extrato_zig!G:G,df_extrato_zig!E:E,Conciliacao!A13,df_extrato_zig!D:D,"Antecipação") | C13: =SUMIFS(df_extrato_zig!E:E,df_extrato_zig!L:L,Conciliacao!A13,df_extrato_zig!F:F,"DINHEIRO") | D13: =SUMIFS(view_parc_agrup!H:H,view_parc_agrup!G:G,Conciliacao!A13) | E13: =SUMIFS(df_eventos!F:F,df_eventos!H:H,Conciliacao!A13) | F13: =SUMIFS(df_mutuos!M:M,df_mutuos!B:B,Conciliacao!A13) | G13: =SUMIFS(df_bloqueios_judiciais!G:G,df_bloqueios_judiciais!D:D,Conciliacao!A13,df_bloqueios_judiciais!G:G,">0") | H13: =SUMIFS(df_extratos!I:I,df_extratos!F:F,">="&Conciliacao!BE13,df_extratos!F:F,"<"&Conciliacao!BE13+1,df_extratos!G:G,"CREDITO") +SUMIFS(df_extratos!I:I,df_extratos!F:F,">="&Conciliacao!A13, df_extratos!F:F,"<"&Conciliacao!A13+1, df_extratos!G:G,"CREDITO") +SUMIFS(df_extratos!I:I,df_extratos!F:F,">="&Conciliacao!BF13,df_extratos!F:F,"<"&Conciliacao!BF13+1,df_extratos!G:G,"CREDITO") +SUMIFS(df_extratos!I:I,df_extratos!F:F,">="&Conciliacao!BG13,df_extratos!F:F,"<"&Conciliacao!BG13+1,df_extratos!G:G,"CREDITO") +SUMIFS(df_extratos!I:I,df_extratos!F:F,">="&Conciliacao!BH13,df_extratos!F:F,"<"&Conciliacao!BH13+1,df_extratos!G:G,"CREDITO") | I13: =H13-SUM(B13:G13) | J13: =SUMIFS(df_blueme_sem_parcelamento!E:E,df_blueme_sem_parcelamento!H:H,Conciliacao!A13)*(-1) | K13: =SUMIFS(df_blueme_com_parcelamento!J:J,df_blueme_com_parcelamento!M:M,Conciliacao!A13)*(-1) | L13: =SUMIFS(df_mutuos!N:N,df_mutuos!B:B,Conciliacao!A13)*(-1) | M13: =SUMIFS(df_bloqueios_judiciais!E:E,df_bloqueios_judiciais!D:D,Conciliacao!A13,df_bloqueios_judiciais!E:E,"<0") | N13: =SUMIFS(df_extratos!I:I,df_extratos!F:F,">="&Conciliacao!BE13,df_extratos!F:F,"<"&Conciliacao!BE13+1,df_extratos!G:G,"DEBITO") +SUMIFS(df_extratos!I:I,df_extratos!F:F,">="&Conciliacao!A13, df_extratos!F:F,"<"&Conciliacao!A13+1, df_extratos!G:G,"DEBITO") +SUMIFS(df_extratos!I:I,df_extratos!F:F,">="&Conciliacao!BF13,df_extratos!F:F,"<"&Conciliacao!BF13+1,df_extratos!G:G,"DEBITO") +SUMIFS(df_extratos!I:I,df_extratos!F:F,">="&Conciliacao!BG13,df_extratos!F:F,"<"&Conciliacao!BG13+1,df_extratos!G:G,"DEBITO") +SUMIFS(df_extratos!I:I,df_extratos!F:F,">="&Conciliacao!BH13,df_extratos!F:F,"<"&Conciliacao!BH13+1,df_extratos!G:G,"DEBITO") | O13: =N13-SUM(J13:M13) | P13: =SUMIFS(df_ajustes_conciliaco!D:D,df_ajustes_conciliaco!C:C,Conciliacao!A13) | Q13: =O13+I13-P13 | BE13: 45669.5 | BF13: 45669.125 | BG13: 45669.542 | BH13: 45669.625
A14: =A13+1 | B14: =-SUMIFS(df_extrato_zig!G:G,df_extrato_zig!E:E,Conciliacao!A14,df_extrato_zig!D:D,"Saque")-SUMIFS(df_extrato_zig!G:G,df_extrato_zig!E:E,Conciliacao!A14,df_extrato_zig!D:D,"Antecipação") | C14: =SUMIFS(df_extrato_zig!E:E,df_extrato_zig!L:L,Conciliacao!A14,df_extrato_zig!F:F,"DINHEIRO") | D14: =SUMIFS(view_parc_agrup!H:H,view_parc_agrup!G:G,Conciliacao!A14) | E14: =SUMIFS(df_eventos!F:F,df_eventos!H:H,Conciliacao!A14) | F14: =SUMIFS(df_mutuos!M:M,df_mutuos!B:B,Conciliacao!A14) | G14: =SUMIFS(df_bloqueios_judiciais!G:G,df_bloqueios_judiciais!D:D,Conciliacao!A14,df_bloqueios_judiciais!G:G,">0") | H14: =SUMIFS(df_extratos!I:I,df_extratos!F:F,">="&Conciliacao!BE14,df_extratos!F:F,"<"&Conciliacao!BE14+1,df_extratos!G:G,"CREDITO") +SUMIFS(df_extratos!I:I,df_extratos!F:F,">="&Conciliacao!A14, df_extratos!F:F,"<"&Conciliacao!A14+1, df_extratos!G:G,"CREDITO") +SUMIFS(df_extratos!I:I,df_extratos!F:F,">="&Conciliacao!BF14,df_extratos!F:F,"<"&Conciliacao!BF14+1,df_extratos!G:G,"CREDITO") +SUMIFS(df_extratos!I:I,df_extratos!F:F,">="&Conciliacao!BG14,df_extratos!F:F,"<"&Conciliacao!BG14+1,df_extratos!G:G,"CREDITO") +SUMIFS(df_extratos!I:I,df_extratos!F:F,">="&Conciliacao!BH14,df_extratos!F:F,"<"&Conciliacao!BH14+1,df_extratos!G:G,"CREDITO") | I14: =H14-SUM(B14:G14) | J14: =SUMIFS(df_blueme_sem_parcelamento!E:E,df_blueme_sem_parcelamento!H:H,Conciliacao!A14)*(-1) | K14: =SUMIFS(df_blueme_com_parcelamento!J:J,df_blueme_com_parcelamento!M:M,Conciliacao!A14)*(-1) | L14: =SUMIFS(df_mutuos!N:N,df_mutuos!B:B,Conciliacao!A14)*(-1) | M14: =SUMIFS(df_bloqueios_judiciais!E:E,df_bloqueios_judiciais!D:D,Conciliacao!A14,df_bloqueios_judiciais!E:E,"<0") | N14: =SUMIFS(df_extratos!I:I,df_extratos!F:F,">="&Conciliacao!BE14,df_extratos!F:F,"<"&Conciliacao!BE14+1,df_extratos!G:G,"DEBITO") +SUMIFS(df_extratos!I:I,df_extratos!F:F,">="&Conciliacao!A14, df_extratos!F:F,"<"&Conciliacao!A14+1, df_extratos!G:G,"DEBITO") +SUMIFS(df_extratos!I:I,df_extratos!F:F,">="&Conciliacao!BF14,df_extratos!F:F,"<"&Conciliacao!BF14+1,df_extratos!G:G,"DEBITO") +SUMIFS(df_extratos!I:I,df_extratos!F:F,">="&Conciliacao!BG14,df_extratos!F:F,"<"&Conciliacao!BG14+1,df_extratos!G:G,"DEBITO") +SUMIFS(df_extratos!I:I,df_extratos!F:F,">="&Conciliacao!BH14,df_extratos!F:F,"<"&Conciliacao!BH14+1,df_extratos!G:G,"DEBITO") | O14: =N14-SUM(J14:M14) | P14: =SUMIFS(df_ajustes_conciliaco!D:D,df_ajustes_conciliaco!C:C,Conciliacao!A14) | Q14: =O14+I14-P14 | BE14: 45670.5 | BF14: 45670.125 | BG14: 45670.542 | BH14: 45670.625
... A34: =A33+1 | B34: =-SUMIFS(df_extrato_zig!G:G,df_extrato_zig!E:E,Conciliacao!A34,df_extrato_zig!D:D,"Saque")-SUMIFS(df_extrato_zig!G:G,df_extrato_zig!E:E,Conciliacao!A34,df_extrato_zig!D:D,"Antecipação") | C34: =SUMIFS(df_extrato_zig!E:E,df_extrato_zig!L:L,Conciliacao!A34,df_extrato_zig!F:F,"DINHEIRO") | D34: =SUMIFS(view_parc_agrup!H:H,view_parc_agrup!G:G,Conciliacao!A34) | E34: =SUMIFS(df_eventos!F:F,df_eventos!H:H,Conciliacao!A34) | F34: =SUMIFS(df_mutuos!M:M,df_mutuos!B:B,Conciliacao!A34) | G34: =SUMIFS(df_bloqueios_judiciais!G:G,df_bloqueios_judiciais!D:D,Conciliacao!A34,df_bloqueios_judiciais!G:G,">0") | H34: =SUMIFS(df_extratos!I:I,df_extratos!F:F,">="&Conciliacao!BE34,df_extratos!F:F,"<"&Conciliacao!BE34+1,df_extratos!G:G,"CREDITO") +SUMIFS(df_extratos!I:I,df_extratos!F:F,">="&Conciliacao!A34, df_extratos!F:F,"<"&Conciliacao!A34+1, df_extratos!G:G,"CREDITO") +SUMIFS(df_extratos!I:I,df_extratos!F:F,">="&Conciliacao!BF34,df_extratos!F:F,"<"&Conciliacao!BF34+1,df_extratos!G:G,"CREDITO") +SUMIFS(df_extratos!I:I,df_extratos!F:F,">="&Conciliacao!BG34,df_extratos!F:F,"<"&Conciliacao!BG34+1,df_extratos!G:G,"CREDITO") +SUMIFS(df_extratos!I:I,df_extratos!F:F,">="&Conciliacao!BH34,df_extratos!F:F,"<"&Conciliacao!BH34+1,df_extratos!G:G,"CREDITO") | I34: =H34-SUM(B34:G34) | J34: =SUMIFS(df_blueme_sem_parcelamento!E:E,df_blueme_sem_parcelamento!H:H,Conciliacao!A34)*(-1) | K34: =SUMIFS(df_blueme_com_parcelamento!J:J,df_blueme_com_parcelamento!M:M,Conciliacao!A34)*(-1) | L34: =SUMIFS(df_mutuos!N:N,df_mutuos!B:B,Conciliacao!A34)*(-1) | M34: =SUMIFS(df_bloqueios_judiciais!E:E,df_bloqueios_judiciais!D:D,Conciliacao!A34,df_bloqueios_judiciais!E:E,"<0") | N34: =SUMIFS(df_extratos!I:I,df_extratos!F:F,">="&Conciliacao!BE34,df_extratos!F:F,"<"&Conciliacao!BE34+1,df_extratos!G:G,"DEBITO") +SUMIFS(df_extratos!I:I,df_extratos!F:F,">="&Conciliacao!A34, df_extratos!F:F,"<"&Conciliacao!A34+1, df_extratos!G:G,"DEBITO") +SUMIFS(df_extratos!I:I,df_extratos!F:F,">="&Conciliacao!BF34,df_extratos!F:F,"<"&Conciliacao!BF34+1,df_extratos!G:G,"DEBITO") +SUMIFS(df_extratos!I:I,df_extratos!F:F,">="&Conciliacao!BG34,df_extratos!F:F,"<"&Conciliacao!BG34+1,df_extratos!G:G,"DEBITO") +SUMIFS(df_extratos!I:I,df_extratos!F:F,">="&Conciliacao!BH34,df_extratos!F:F,"<"&Conciliacao!BH34+1,df_extratos!G:G,"DEBITO") | O34: =N34-SUM(J34:M34) | P34: =SUMIFS(df_ajustes_conciliaco!D:D,df_ajustes_conciliaco!C:C,Conciliacao!A34) | Q34: =O34+I34-P34 | BE34: 45690.5 | BF34: 45690.125 | BG34: 45690.542 | BH34: 45690.625
A35: =A34+1 | B35: =-SUMIFS(df_extrato_zig!G:G,df_extrato_zig!E:E,Conciliacao!A35,df_extrato_zig!D:D,"Saque")-SUMIFS(df_extrato_zig!G:G,df_extrato_zig!E:E,Conciliacao!A35,df_extrato_zig!D:D,"Antecipação") | C35: =SUMIFS(df_extrato_zig!E:E,df_extrato_zig!L:L,Conciliacao!A35,df_extrato_zig!F:F,"DINHEIRO") | D35: =SUMIFS(view_parc_agrup!H:H,view_parc_agrup!G:G,Conciliacao!A35) | E35: =SUMIFS(df_eventos!F:F,df_eventos!H:H,Conciliacao!A35) | F35: =SUMIFS(df_mutuos!M:M,df_mutuos!B:B,Conciliacao!A35) | G35: =SUMIFS(df_bloqueios_judiciais!G:G,df_bloqueios_judiciais!D:D,Conciliacao!A35,df_bloqueios_judiciais!G:G,">0") | H35: =SUMIFS(df_extratos!I:I,df_extratos!F:F,">="&Conciliacao!BE35,df_extratos!F:F,"<"&Conciliacao!BE35+1,df_extratos!G:G,"CREDITO") +SUMIFS(df_extratos!I:I,df_extratos!F:F,">="&Conciliacao!A35, df_extratos!F:F,"<"&Conciliacao!A35+1, df_extratos!G:G,"CREDITO") +SUMIFS(df_extratos!I:I,df_extratos!F:F,">="&Conciliacao!BF35,df_extratos!F:F,"<"&Conciliacao!BF35+1,df_extratos!G:G,"CREDITO") +SUMIFS(df_extratos!I:I,df_extratos!F:F,">="&Conciliacao!BG35,df_extratos!F:F,"<"&Conciliacao!BG35+1,df_extratos!G:G,"CREDITO") +SUMIFS(df_extratos!I:I,df_extratos!F:F,">="&Conciliacao!BH35,df_extratos!F:F,"<"&Conciliacao!BH35+1,df_extratos!G:G,"CREDITO") | I35: =H35-SUM(B35:G35) | J35: =SUMIFS(df_blueme_sem_parcelamento!E:E,df_blueme_sem_parcelamento!H:H,Conciliacao!A35)*(-1) | K35: =SUMIFS(df_blueme_com_parcelamento!J:J,df_blueme_com_parcelamento!M:M,Conciliacao!A35)*(-1) | L35: =SUMIFS(df_mutuos!N:N,df_mutuos!B:B,Conciliacao!A35)*(-1) | M35: =SUMIFS(df_bloqueios_judiciais!G:G,df_bloqueios_judiciais!D:D,Conciliacao!A35,df_bloqueios_judiciais!G:G,"<0") | N35: =SUMIFS(df_extratos!I:I,df_extratos!F:F,">="&Conciliacao!BE35,df_extratos!F:F,"<"&Conciliacao!BE35+1,df_extratos!G:G,"DEBITO") +SUMIFS(df_extratos!I:I,df_extratos!F:F,">="&Conciliacao!A35, df_extratos!F:F,"<"&Conciliacao!A35+1, df_extratos!G:G,"DEBITO") +SUMIFS(df_extratos!I:I,df_extratos!F:F,">="&Conciliacao!BF35,df_extratos!F:F,"<"&Conciliacao!BF35+1,df_extratos!G:G,"DEBITO") +SUMIFS(df_extratos!I:I,df_extratos!F:F,">="&Conciliacao!BG35,df_extratos!F:F,"<"&Conciliacao!BG35+1,df_extratos!G:G,"DEBITO") +SUMIFS(df_extratos!I:I,df_extratos!F:F,">="&Conciliacao!BH35,df_extratos!F:F,"<"&Conciliacao!BH35+1,df_extratos!G:G,"DEBITO") | O35: =N35-SUM(J35:M35) | P35: =SUMIFS(df_ajustes_conciliaco!D:D,df_ajustes_conciliaco!C:C,Conciliacao!A35) | Q35: =O35+I35-P35 | BE35: 45691.5 | BF35: 45691.125 | BG35: 45691.542 | BH35: 45691.625
A36: =A35+1 | B36: =-SUMIFS(df_extrato_zig!G:G,df_extrato_zig!E:E,Conciliacao!A36,df_extrato_zig!D:D,"Saque")-SUMIFS(df_extrato_zig!G:G,df_extrato_zig!E:E,Conciliacao!A36,df_extrato_zig!D:D,"Antecipação") | C36: =SUMIFS(df_extrato_zig!E:E,df_extrato_zig!L:L,Conciliacao!A36,df_extrato_zig!F:F,"DINHEIRO") | D36: =SUMIFS(view_parc_agrup!H:H,view_parc_agrup!G:G,Conciliacao!A36) | E36: =SUMIFS(df_eventos!F:F,df_eventos!H:H,Conciliacao!A36) | F36: =SUMIFS(df_mutuos!M:M,df_mutuos!B:B,Conciliacao!A36) | G36: =SUMIFS(df_bloqueios_judiciais!G:G,df_bloqueios_judiciais!D:D,Conciliacao!A36,df_bloqueios_judiciais!G:G,">0") | H36: =SUMIFS(df_extratos!I:I,df_extratos!F:F,">="&Conciliacao!BE36,df_extratos!F:F,"<"&Conciliacao!BE36+1,df_extratos!G:G,"CREDITO") +SUMIFS(df_extratos!I:I,df_extratos!F:F,">="&Conciliacao!A36, df_extratos!F:F,"<"&Conciliacao!A36+1, df_extratos!G:G,"CREDITO") +SUMIFS(df_extratos!I:I,df_extratos!F:F,">="&Conciliacao!BF36,df_extratos!F:F,"<"&Conciliacao!BF36+1,df_extratos!G:G,"CREDITO") +SUMIFS(df_extratos!I:I,df_extratos!F:F,">="&Conciliacao!BG36,df_extratos!F:F,"<"&Conciliacao!BG36+1,df_extratos!G:G,"CREDITO") +SUMIFS(df_extratos!I:I,df_extratos!F:F,">="&Conciliacao!BH36,df_extratos!F:F,"<"&Conciliacao!BH36+1,df_extratos!G:G,"CREDITO") | I36: =H36-SUM(B36:G36) | J36: =SUMIFS(df_blueme_sem_parcelamento!E:E,df_blueme_sem_parcelamento!H:H,Conciliacao!A36)*(-1) | K36: =SUMIFS(df_blueme_com_parcelamento!J:J,df_blueme_com_parcelamento!M:M,Conciliacao!A36)*(-1) | L36: =SUMIFS(df_mutuos!N:N,df_mutuos!B:B,Conciliacao!A36)*(-1) | M36: =SUMIFS(df_bloqueios_judiciais!G:G,df_bloqueios_judiciais!D:D,Conciliacao!A36,df_bloqueios_judiciais!G:G,"<0") | N36: =SUMIFS(df_extratos!I:I,df_extratos!F:F,">="&Conciliacao!BE36,df_extratos!F:F,"<"&Conciliacao!BE36+1,df_extratos!G:G,"DEBITO") +SUMIFS(df_extratos!I:I,df_extratos!F:F,">="&Conciliacao!A36, df_extratos!F:F,"<"&Conciliacao!A36+1, df_extratos!G:G,"DEBITO") +SUMIFS(df_extratos!I:I,df_extratos!F:F,">="&Conciliacao!BF36,df_extratos!F:F,"<"&Conciliacao!BF36+1,df_extratos!G:G,"DEBITO") +SUMIFS(df_extratos!I:I,df_extratos!F:F,">="&Conciliacao!BG36,df_extratos!F:F,"<"&Conciliacao!BG36+1,df_extratos!G:G,"DEBITO") +SUMIFS(df_extratos!I:I,df_extratos!F:F,">="&Conciliacao!BH36,df_extratos!F:F,"<"&Conciliacao!BH36+1,df_extratos!G:G,"DEBITO") | O36: =N36-SUM(J36:M36) | P36: =SUMIFS(df_ajustes_conciliaco!D:D,df_ajustes_conciliaco!C:C,Conciliacao!A36) | Q36: =O36+I36-P36 | BE36: 45692.5 | BF36: 45692.125 | BG36: 45692.542 | BH36: 45692.625
A37: =A36+1 | B37: =-SUMIFS(df_extrato_zig!G:G,df_extrato_zig!E:E,Conciliacao!A37,df_extrato_zig!D:D,"Saque")-SUMIFS(df_extrato_zig!G:G,df_extrato_zig!E:E,Conciliacao!A37,df_extrato_zig!D:D,"Antecipação") | C37: =SUMIFS(df_extrato_zig!E:E,df_extrato_zig!L:L,Conciliacao!A37,df_extrato_zig!F:F,"DINHEIRO") | D37: =SUMIFS(view_parc_agrup!H:H,view_parc_agrup!G:G,Conciliacao!A37) | E37: =SUMIFS(df_eventos!F:F,df_eventos!H:H,Conciliacao!A37) | F37: =SUMIFS(df_mutuos!M:M,df_mutuos!B:B,Conciliacao!A37) | G37: =SUMIFS(df_bloqueios_judiciais!G:G,df_bloqueios_judiciais!D:D,Conciliacao!A37,df_bloqueios_judiciais!G:G,">0") | H37: =SUMIFS(df_extratos!I:I,df_extratos!F:F,">="&Conciliacao!BE37,df_extratos!F:F,"<"&Conciliacao!BE37+1,df_extratos!G:G,"CREDITO") +SUMIFS(df_extratos!I:I,df_extratos!F:F,">="&Conciliacao!A37, df_extratos!F:F,"<"&Conciliacao!A37+1, df_extratos!G:G,"CREDITO") +SUMIFS(df_extratos!I:I,df_extratos!F:F,">="&Conciliacao!BF37,df_extratos!F:F,"<"&Conciliacao!BF37+1,df_extratos!G:G,"CREDITO") +SUMIFS(df_extratos!I:I,df_extratos!F:F,">="&Conciliacao!BG37,df_extratos!F:F,"<"&Conciliacao!BG37+1,df_extratos!G:G,"CREDITO") +SUMIFS(df_extratos!I:I,df_extratos!F:F,">="&Conciliacao!BH37,df_extratos!F:F,"<"&Conciliacao!BH37+1,df_extratos!G:G,"CREDITO") | I37: =H37-SUM(B37:G37) | J37: =SUMIFS(df_blueme_sem_parcelamento!E:E,df_blueme_sem_parcelamento!H:H,Conciliacao!A37)*(-1) | K37: =SUMIFS(df_blueme_com_parcelamento!J:J,df_blueme_com_parcelamento!M:M,Conciliacao!A37)*(-1) | L37: =SUMIFS(df_mutuos!N:N,df_mutuos!B:B,Conciliacao!A37)*(-1) | M37: =SUMIFS(df_bloqueios_judiciais!G:G,df_bloqueios_judiciais!D:D,Conciliacao!A37,df_bloqueios_judiciais!G:G,"<0") | N37: =SUMIFS(df_extratos!I:I,df_extratos!F:F,">="&Conciliacao!BE37,df_extratos!F:F,"<"&Conciliacao!BE37+1,df_extratos!G:G,"DEBITO") +SUMIFS(df_extratos!I:I,df_extratos!F:F,">="&Conciliacao!A37, df_extratos!F:F,"<"&Conciliacao!A37+1, df_extratos!G:G,"DEBITO") +SUMIFS(df_extratos!I:I,df_extratos!F:F,">="&Conciliacao!BF37,df_extratos!F:F,"<"&Conciliacao!BF37+1,df_extratos!G:G,"DEBITO") +SUMIFS(df_extratos!I:I,df_extratos!F:F,">="&Conciliacao!BG37,df_extratos!F:F,"<"&Conciliacao!BG37+1,df_extratos!G:G,"DEBITO") +SUMIFS(df_extratos!I:I,df_extratos!F:F,">="&Conciliacao!BH37,df_extratos!F:F,"<"&Conciliacao!BH37+1,df_extratos!G:G,"DEBITO") | O37: =N37-SUM(J37:M37) | P37: =SUMIFS(df_ajustes_conciliaco!D:D,df_ajustes_conciliaco!C:C,Conciliacao!A37) | Q37: =O37+I37-P37 | BE37: 45693.5 | BF37: 45693.125 | BG37: 45693.542 | BH37: 45693.625
A38: =A37+1 | B38: =-SUMIFS(df_extrato_zig!G:G,df_extrato_zig!E:E,Conciliacao!A38,df_extrato_zig!D:D,"Saque")-SUMIFS(df_extrato_zig!G:G,df_extrato_zig!E:E,Conciliacao!A38,df_extrato_zig!D:D,"Antecipação") | C38: =SUMIFS(df_extrato_zig!E:E,df_extrato_zig!L:L,Conciliacao!A38,df_extrato_zig!F:F,"DINHEIRO") | D38: =SUMIFS(view_parc_agrup!H:H,view_parc_agrup!G:G,Conciliacao!A38) | E38: =SUMIFS(df_eventos!F:F,df_eventos!H:H,Conciliacao!A38) | F38: =SUMIFS(df_mutuos!M:M,df_mutuos!B:B,Conciliacao!A38) | G38: =SUMIFS(df_bloqueios_judiciais!G:G,df_bloqueios_judiciais!D:D,Conciliacao!A38,df_bloqueios_judiciais!G:G,">0") | H38: =SUMIFS(df_extratos!I:I,df_extratos!F:F,">="&Conciliacao!BE38,df_extratos!F:F,"<"&Conciliacao!BE38+1,df_extratos!G:G,"CREDITO") +SUMIFS(df_extratos!I:I,df_extratos!F:F,">="&Conciliacao!A38, df_extratos!F:F,"<"&Conciliacao!A38+1, df_extratos!G:G,"CREDITO") +SUMIFS(df_extratos!I:I,df_extratos!F:F,">="&Conciliacao!BF38,df_extratos!F:F,"<"&Conciliacao!BF38+1,df_extratos!G:G,"CREDITO") +SUMIFS(df_extratos!I:I,df_extratos!F:F,">="&Conciliacao!BG38,df_extratos!F:F,"<"&Conciliacao!BG38+1,df_extratos!G:G,"CREDITO") +SUMIFS(df_extratos!I:I,df_extratos!F:F,">="&Conciliacao!BH38,df_extratos!F:F,"<"&Conciliacao!BH38+1,df_extratos!G:G,"CREDITO") | I38: =H38-SUM(B38:G38) | J38: =SUMIFS(df_blueme_sem_parcelamento!E:E,df_blueme_sem_parcelamento!H:H,Conciliacao!A38)*(-1) | K38: =SUMIFS(df_blueme_com_parcelamento!J:J,df_blueme_com_parcelamento!M:M,Conciliacao!A38)*(-1) | L38: =SUMIFS(df_mutuos!N:N,df_mutuos!B:B,Conciliacao!A38)*(-1) | M38: =SUMIFS(df_bloqueios_judiciais!G:G,df_bloqueios_judiciais!D:D,Conciliacao!A38,df_bloqueios_judiciais!G:G,"<0") | N38: =SUMIFS(df_extratos!I:I,df_extratos!F:F,">="&Conciliacao!BE38,df_extratos!F:F,"<"&Conciliacao!BE38+1,df_extratos!G:G,"DEBITO") +SUMIFS(df_extratos!I:I,df_extratos!F:F,">="&Conciliacao!A38, df_extratos!F:F,"<"&Conciliacao!A38+1, df_extratos!G:G,"DEBITO") +SUMIFS(df_extratos!I:I,df_extratos!F:F,">="&Conciliacao!BF38,df_extratos!F:F,"<"&Conciliacao!BF38+1,df_extratos!G:G,"DEBITO") +SUMIFS(df_extratos!I:I,df_extratos!F:F,">="&Conciliacao!BG38,df_extratos!F:F,"<"&Conciliacao!BG38+1,df_extratos!G:G,"DEBITO") +SUMIFS(df_extratos!I:I,df_extratos!F:F,">="&Conciliacao!BH38,df_extratos!F:F,"<"&Conciliacao!BH38+1,df_extratos!G:G,"DEBITO") | O38: =N38-SUM(J38:M38) | P38: =SUMIFS(df_ajustes_conciliaco!D:D,df_ajustes_conciliaco!C:C,Conciliacao!A38) | Q38: =O38+I38-P38 | BE38: 45694.5 | BF38: 45694.125 | BG38: 45694.542 | BH38: 45694.625
A39: =A38+1 | B39: =-SUMIFS(df_extrato_zig!G:G,df_extrato_zig!E:E,Conciliacao!A39,df_extrato_zig!D:D,"Saque")-SUMIFS(df_extrato_zig!G:G,df_extrato_zig!E:E,Conciliacao!A39,df_extrato_zig!D:D,"Antecipação") | C39: =SUMIFS(df_extrato_zig!E:E,df_extrato_zig!L:L,Conciliacao!A39,df_extrato_zig!F:F,"DINHEIRO") | D39: =SUMIFS(view_parc_agrup!H:H,view_parc_agrup!G:G,Conciliacao!A39) | E39: =SUMIFS(df_eventos!F:F,df_eventos!H:H,Conciliacao!A39) | F39: =SUMIFS(df_mutuos!M:M,df_mutuos!B:B,Conciliacao!A39) | G39: =SUMIFS(df_bloqueios_judiciais!G:G,df_bloqueios_judiciais!D:D,Conciliacao!A39,df_bloqueios_judiciais!G:G,">0") | H39: =SUMIFS(df_extratos!I:I,df_extratos!F:F,">="&Conciliacao!BE39,df_extratos!F:F,"<"&Conciliacao!BE39+1,df_extratos!G:G,"CREDITO") +SUMIFS(df_extratos!I:I,df_extratos!F:F,">="&Conciliacao!A39, df_extratos!F:F,"<"&Conciliacao!A39+1, df_extratos!G:G,"CREDITO") +SUMIFS(df_extratos!I:I,df_extratos!F:F,">="&Conciliacao!BF39,df_extratos!F:F,"<"&Conciliacao!BF39+1,df_extratos!G:G,"CREDITO") +SUMIFS(df_extratos!I:I,df_extratos!F:F,">="&Conciliacao!BG39,df_extratos!F:F,"<"&Conciliacao!BG39+1,df_extratos!G:G,"CREDITO") +SUMIFS(df_extratos!I:I,df_extratos!F:F,">="&Conciliacao!BH39,df_extratos!F:F,"<"&Conciliacao!BH39+1,df_extratos!G:G,"CREDITO") | I39: =H39-SUM(B39:G39) | J39: =SUMIFS(df_blueme_sem_parcelamento!E:E,df_blueme_sem_parcelamento!H:H,Conciliacao!A39)*(-1) | K39: =SUMIFS(df_blueme_com_parcelamento!J:J,df_blueme_com_parcelamento!M:M,Conciliacao!A39)*(-1) | L39: =SUMIFS(df_mutuos!N:N,df_mutuos!B:B,Conciliacao!A39)*(-1) | M39: =SUMIFS(df_bloqueios_judiciais!G:G,df_bloqueios_judiciais!D:D,Conciliacao!A39,df_bloqueios_judiciais!G:G,"<0") | N39: =SUMIFS(df_extratos!I:I,df_extratos!F:F,">="&Conciliacao!BE39,df_extratos!F:F,"<"&Conciliacao!BE39+1,df_extratos!G:G,"DEBITO") +SUMIFS(df_extratos!I:I,df_extratos!F:F,">="&Conciliacao!A39, df_extratos!F:F,"<"&Conciliacao!A39+1, df_extratos!G:G,"DEBITO") +SUMIFS(df_extratos!I:I,df_extratos!F:F,">="&Conciliacao!BF39,df_extratos!F:F,"<"&Conciliacao!BF39+1,df_extratos!G:G,"DEBITO") +SUMIFS(df_extratos!I:I,df_extratos!F:F,">="&Conciliacao!BG39,df_extratos!F:F,"<"&Conciliacao!BG39+1,df_extratos!G:G,"DEBITO") +SUMIFS(df_extratos!I:I,df_extratos!F:F,">="&Conciliacao!BH39,df_extratos!F:F,"<"&Conciliacao!BH39+1,df_extratos!G:G,"DEBITO") | O39: =N39-SUM(J39:M39) | P39: =SUMIFS(df_ajustes_conciliaco!D:D,df_ajustes_conciliaco!C:C,Conciliacao!A39) | Q39: =O39+I39-P39 | BE39: 45695.5 | BF39: 45695.125 | BG39: 45695.542 | BH39: 45695.625
A40: =A39+1 | B40: =-SUMIFS(df_extrato_zig!G:G,df_extrato_zig!E:E,Conciliacao!A40,df_extrato_zig!D:D,"Saque")-SUMIFS(df_extrato_zig!G:G,df_extrato_zig!E:E,Conciliacao!A40,df_extrato_zig!D:D,"Antecipação") | C40: =SUMIFS(df_extrato_zig!E:E,df_extrato_zig!L:L,Conciliacao!A40,df_extrato_zig!F:F,"DINHEIRO") | D40: =SUMIFS(view_parc_agrup!H:H,view_parc_agrup!G:G,Conciliacao!A40) | E40: =SUMIFS(df_eventos!F:F,df_eventos!H:H,Conciliacao!A40) | F40: =SUMIFS(df_mutuos!M:M,df_mutuos!B:B,Conciliacao!A40) | G40: =SUMIFS(df_bloqueios_judiciais!G:G,df_bloqueios_judiciais!D:D,Conciliacao!A40,df_bloqueios_judiciais!G:G,">0") | H40: =SUMIFS(df_extratos!I:I,df_extratos!F:F,">="&Conciliacao!BE40,df_extratos!F:F,"<"&Conciliacao!BE40+1,df_extratos!G:G,"CREDITO") +SUMIFS(df_extratos!I:I,df_extratos!F:F,">="&Conciliacao!A40, df_extratos!F:F,"<"&Conciliacao!A40+1, df_extratos!G:G,"CREDITO") +SUMIFS(df_extratos!I:I,df_extratos!F:F,">="&Conciliacao!BF40,df_extratos!F:F,"<"&Conciliacao!BF40+1,df_extratos!G:G,"CREDITO") +SUMIFS(df_extratos!I:I,df_extratos!F:F,">="&Conciliacao!BG40,df_extratos!F:F,"<"&Conciliacao!BG40+1,df_extratos!G:G,"CREDITO") +SUMIFS(df_extratos!I:I,df_extratos!F:F,">="&Conciliacao!BH40,df_extratos!F:F,"<"&Conciliacao!BH40+1,df_extratos!G:G,"CREDITO") | I40: =H40-SUM(B40:G40) | J40: =SUMIFS(df_blueme_sem_parcelamento!E:E,df_blueme_sem_parcelamento!H:H,Conciliacao!A40)*(-1) | K40: =SUMIFS(df_blueme_com_parcelamento!J:J,df_blueme_com_parcelamento!M:M,Conciliacao!A40)*(-1) | L40: =SUMIFS(df_mutuos!N:N,df_mutuos!B:B,Conciliacao!A40)*(-1) | M40: =SUMIFS(df_bloqueios_judiciais!G:G,df_bloqueios_judiciais!D:D,Conciliacao!A40,df_bloqueios_judiciais!G:G,"<0") | N40: =SUMIFS(df_extratos!I:I,df_extratos!F:F,">="&Conciliacao!BE40,df_extratos!F:F,"<"&Conciliacao!BE40+1,df_extratos!G:G,"DEBITO") +SUMIFS(df_extratos!I:I,df_extratos!F:F,">="&Conciliacao!A40, df_extratos!F:F,"<"&Conciliacao!A40+1, df_extratos!G:G,"DEBITO") +SUMIFS(df_extratos!I:I,df_extratos!F:F,">="&Conciliacao!BF40,df_extratos!F:F,"<"&Conciliacao!BF40+1,df_extratos!G:G,"DEBITO") +SUMIFS(df_extratos!I:I,df_extratos!F:F,">="&Conciliacao!BG40,df_extratos!F:F,"<"&Conciliacao!BG40+1,df_extratos!G:G,"DEBITO") +SUMIFS(df_extratos!I:I,df_extratos!F:F,">="&Conciliacao!BH40,df_extratos!F:F,"<"&Conciliacao!BH40+1,df_extratos!G:G,"DEBITO") | O40: =N40-SUM(J40:M40) | P40: =SUMIFS(df_ajustes_conciliaco!D:D,df_ajustes_conciliaco!C:C,Conciliacao!A40) | Q40: =O40+I40-P40 | BE40: 45696.5 | BF40: 45696.125 | BG40: 45696.542 | BH40: 45696.625
A41: =A40+1 | B41: =-SUMIFS(df_extrato_zig!G:G,df_extrato_zig!E:E,Conciliacao!A41,df_extrato_zig!D:D,"Saque")-SUMIFS(df_extrato_zig!G:G,df_extrato_zig!E:E,Conciliacao!A41,df_extrato_zig!D:D,"Antecipação") | C41: =SUMIFS(df_extrato_zig!E:E,df_extrato_zig!L:L,Conciliacao!A41,df_extrato_zig!F:F,"DINHEIRO") | D41: =SUMIFS(view_parc_agrup!H:H,view_parc_agrup!G:G,Conciliacao!A41) | E41: =SUMIFS(df_eventos!F:F,df_eventos!H:H,Conciliacao!A41) | F41: =SUMIFS(df_mutuos!M:M,df_mutuos!B:B,Conciliacao!A41) | G41: =SUMIFS(df_bloqueios_judiciais!G:G,df_bloqueios_judiciais!D:D,Conciliacao!A41,df_bloqueios_judiciais!G:G,">0") | H41: =SUMIFS(df_extratos!I:I,df_extratos!F:F,">="&Conciliacao!BE41,df_extratos!F:F,"<"&Conciliacao!BE41+1,df_extratos!G:G,"CREDITO") +SUMIFS(df_extratos!I:I,df_extratos!F:F,">="&Conciliacao!A41, df_extratos!F:F,"<"&Conciliacao!A41+1, df_extratos!G:G,"CREDITO") +SUMIFS(df_extratos!I:I,df_extratos!F:F,">="&Conciliacao!BF41,df_extratos!F:F,"<"&Conciliacao!BF41+1,df_extratos!G:G,"CREDITO") +SUMIFS(df_extratos!I:I,df_extratos!F:F,">="&Conciliacao!BG41,df_extratos!F:F,"<"&Conciliacao!BG41+1,df_extratos!G:G,"CREDITO") +SUMIFS(df_extratos!I:I,df_extratos!F:F,">="&Conciliacao!BH41,df_extratos!F:F,"<"&Conciliacao!BH41+1,df_extratos!G:G,"CREDITO") | I41: =H41-SUM(B41:G41) | J41: =SUMIFS(df_blueme_sem_parcelamento!E:E,df_blueme_sem_parcelamento!H:H,Conciliacao!A41)*(-1) | K41: =SUMIFS(df_blueme_com_parcelamento!J:J,df_blueme_com_parcelamento!M:M,Conciliacao!A41)*(-1) | L41: =SUMIFS(df_mutuos!N:N,df_mutuos!B:B,Conciliacao!A41)*(-1) | M41: =SUMIFS(df_bloqueios_judiciais!G:G,df_bloqueios_judiciais!D:D,Conciliacao!A41,df_bloqueios_judiciais!G:G,"<0") | N41: =SUMIFS(df_extratos!I:I,df_extratos!F:F,">="&Conciliacao!BE41,df_extratos!F:F,"<"&Conciliacao!BE41+1,df_extratos!G:G,"DEBITO") +SUMIFS(df_extratos!I:I,df_extratos!F:F,">="&Conciliacao!A41, df_extratos!F:F,"<"&Conciliacao!A41+1, df_extratos!G:G,"DEBITO") +SUMIFS(df_extratos!I:I,df_extratos!F:F,">="&Conciliacao!BF41,df_extratos!F:F,"<"&Conciliacao!BF41+1,df_extratos!G:G,"DEBITO") +SUMIFS(df_extratos!I:I,df_extratos!F:F,">="&Conciliacao!BG41,df_extratos!F:F,"<"&Conciliacao!BG41+1,df_extratos!G:G,"DEBITO") +SUMIFS(df_extratos!I:I,df_extratos!F:F,">="&Conciliacao!BH41,df_extratos!F:F,"<"&Conciliacao!BH41+1,df_extratos!G:G,"DEBITO") | O41: =N41-SUM(J41:M41) | P41: =SUMIFS(df_ajustes_conciliaco!D:D,df_ajustes_conciliaco!C:C,Conciliacao!A41) | Q41: =O41+I41-P41 | BE41: 45697.5 | BF41: 45697.125 | BG41: 45697.542 | BH41: 45697.625
A42: =A41+1 | B42: =-SUMIFS(df_extrato_zig!G:G,df_extrato_zig!E:E,Conciliacao!A42,df_extrato_zig!D:D,"Saque")-SUMIFS(df_extrato_zig!G:G,df_extrato_zig!E:E,Conciliacao!A42,df_extrato_zig!D:D,"Antecipação") | C42: =SUMIFS(df_extrato_zig!E:E,df_extrato_zig!L:L,Conciliacao!A42,df_extrato_zig!F:F,"DINHEIRO") | D42: =SUMIFS(view_parc_agrup!H:H,view_parc_agrup!G:G,Conciliacao!A42) | E42: =SUMIFS(df_eventos!F:F,df_eventos!H:H,Conciliacao!A42) | F42: =SUMIFS(df_mutuos!M:M,df_mutuos!B:B,Conciliacao!A42) | G42: =SUMIFS(df_bloqueios_judiciais!G:G,df_bloqueios_judiciais!D:D,Conciliacao!A42,df_bloqueios_judiciais!G:G,">0") | H42: =SUMIFS(df_extratos!I:I,df_extratos!F:F,">="&Conciliacao!BE42,df_extratos!F:F,"<"&Conciliacao!BE42+1,df_extratos!G:G,"CREDITO") +SUMIFS(df_extratos!I:I,df_extratos!F:F,">="&Conciliacao!A42, df_extratos!F:F,"<"&Conciliacao!A42+1, df_extratos!G:G,"CREDITO") +SUMIFS(df_extratos!I:I,df_extratos!F:F,">="&Conciliacao!BF42,df_extratos!F:F,"<"&Conciliacao!BF42+1,df_extratos!G:G,"CREDITO") +SUMIFS(df_extratos!I:I,df_extratos!F:F,">="&Conciliacao!BG42,df_extratos!F:F,"<"&Conciliacao!BG42+1,df_extratos!G:G,"CREDITO") +SUMIFS(df_extratos!I:I,df_extratos!F:F,">="&Conciliacao!BH42,df_extratos!F:F,"<"&Conciliacao!BH42+1,df_extratos!G:G,"CREDITO") | I42: =H42-SUM(B42:G42) | J42: =SUMIFS(df_blueme_sem_parcelamento!E:E,df_blueme_sem_parcelamento!H:H,Conciliacao!A42)*(-1) | K42: =SUMIFS(df_blueme_com_parcelamento!J:J,df_blueme_com_parcelamento!M:M,Conciliacao!A42)*(-1) | L42: =SUMIFS(df_mutuos!N:N,df_mutuos!B:B,Conciliacao!A42)*(-1) | M42: =SUMIFS(df_bloqueios_judiciais!G:G,df_bloqueios_judiciais!D:D,Conciliacao!A42,df_bloqueios_judiciais!G:G,"<0") | N42: =SUMIFS(df_extratos!I:I,df_extratos!F:F,">="&Conciliacao!BE42,df_extratos!F:F,"<"&Conciliacao!BE42+1,df_extratos!G:G,"DEBITO") +SUMIFS(df_extratos!I:I,df_extratos!F:F,">="&Conciliacao!A42, df_extratos!F:F,"<"&Conciliacao!A42+1, df_extratos!G:G,"DEBITO") +SUMIFS(df_extratos!I:I,df_extratos!F:F,">="&Conciliacao!BF42,df_extratos!F:F,"<"&Conciliacao!BF42+1,df_extratos!G:G,"DEBITO") +SUMIFS(df_extratos!I:I,df_extratos!F:F,">="&Conciliacao!BG42,df_extratos!F:F,"<"&Conciliacao!BG42+1,df_extratos!G:G,"DEBITO") +SUMIFS(df_extratos!I:I,df_extratos!F:F,">="&Conciliacao!BH42,df_extratos!F:F,"<"&Conciliacao!BH42+1,df_extratos!G:G,"DEBITO") | O42: =N42-SUM(J42:M42) | P42: =SUMIFS(df_ajustes_conciliaco!D:D,df_ajustes_conciliaco!C:C,Conciliacao!A42) | Q42: =O42+I42-P42 | BE42: 45698.5 | BF42: 45698.125 | BG42: 45698.542 | BH42: 45698.625
A43: =A42+1 | B43: =-SUMIFS(df_extrato_zig!G:G,df_extrato_zig!E:E,Conciliacao!A43,df_extrato_zig!D:D,"Saque")-SUMIFS(df_extrato_zig!G:G,df_extrato_zig!E:E,Conciliacao!A43,df_extrato_zig!D:D,"Antecipação") | C43: =SUMIFS(df_extrato_zig!E:E,df_extrato_zig!L:L,Conciliacao!A43,df_extrato_zig!F:F,"DINHEIRO") | D43: =SUMIFS(view_parc_agrup!H:H,view_parc_agrup!G:G,Conciliacao!A43) | E43: =SUMIFS(df_eventos!F:F,df_eventos!H:H,Conciliacao!A43) | F43: =SUMIFS(df_mutuos!M:M,df_mutuos!B:B,Conciliacao!A43) | G43: =SUMIFS(df_bloqueios_judiciais!G:G,df_bloqueios_judiciais!D:D,Conciliacao!A43,df_bloqueios_judiciais!G:G,">0") | H43: =SUMIFS(df_extratos!I:I,df_extratos!F:F,">="&Conciliacao!BE43,df_extratos!F:F,"<"&Conciliacao!BE43+1,df_extratos!G:G,"CREDITO") +SUMIFS(df_extratos!I:I,df_extratos!F:F,">="&Conciliacao!A43, df_extratos!F:F,"<"&Conciliacao!A43+1, df_extratos!G:G,"CREDITO") +SUMIFS(df_extratos!I:I,df_extratos!F:F,">="&Conciliacao!BF43,df_extratos!F:F,"<"&Conciliacao!BF43+1,df_extratos!G:G,"CREDITO") +SUMIFS(df_extratos!I:I,df_extratos!F:F,">="&Conciliacao!BG43,df_extratos!F:F,"<"&Conciliacao!BG43+1,df_extratos!G:G,"CREDITO") +SUMIFS(df_extratos!I:I,df_extratos!F:F,">="&Conciliacao!BH43,df_extratos!F:F,"<"&Conciliacao!BH43+1,df_extratos!G:G,"CREDITO") | I43: =H43-SUM(B43:G43) | J43: =SUMIFS(df_blueme_sem_parcelamento!E:E,df_blueme_sem_parcelamento!H:H,Conciliacao!A43)*(-1) | K43: =SUMIFS(df_blueme_com_parcelamento!J:J,df_blueme_com_parcelamento!M:M,Conciliacao!A43)*(-1) | L43: =SUMIFS(df_mutuos!N:N,df_mutuos!B:B,Conciliacao!A43)*(-1) | M43: =SUMIFS(df_bloqueios_judiciais!G:G,df_bloqueios_judiciais!D:D,Conciliacao!A43,df_bloqueios_judiciais!G:G,"<0") | N43: =SUMIFS(df_extratos!I:I,df_extratos!F:F,">="&Conciliacao!BE43,df_extratos!F:F,"<"&Conciliacao!BE43+1,df_extratos!G:G,"DEBITO") +SUMIFS(df_extratos!I:I,df_extratos!F:F,">="&Conciliacao!A43, df_extratos!F:F,"<"&Conciliacao!A43+1, df_extratos!G:G,"DEBITO") +SUMIFS(df_extratos!I:I,df_extratos!F:F,">="&Conciliacao!BF43,df_extratos!F:F,"<"&Conciliacao!BF43+1,df_extratos!G:G,"DEBITO") +SUMIFS(df_extratos!I:I,df_extratos!F:F,">="&Conciliacao!BG43,df_extratos!F:F,"<"&Conciliacao!BG43+1,df_extratos!G:G,"DEBITO") +SUMIFS(df_extratos!I:I,df_extratos!F:F,">="&Conciliacao!BH43,df_extratos!F:F,"<"&Conciliacao!BH43+1,df_extratos!G:G,"DEBITO") | O43: =N43-SUM(J43:M43) | P43: =SUMIFS(df_ajustes_conciliaco!D:D,df_ajustes_conciliaco!C:C,Conciliacao!A43) | Q43: =O43+I43-P43 | BE43: 45699.5 | BF43: 45699.125 | BG43: 45699.542 | BH43: 45699.625
