Workbook

Sheet DRE
A3: NUV GASTROBAR | H3: =J8/H8 | J3: =J8/I8 | K3: =M8/K8 | M3: =M8/L8 | N3: =P8/N8 | P3: =P8/O8 | Q3: =S8/Q8 | S3: =S8/R8 | T3: =V8/T8 | V3: =V8/U8 | W3: =Y8/W8 | Y3: =Y8/X8 | Z3: =AB8/Z8 | AB3: =AB8/AA8 | AC3: =AE8/AC8 | AE3: =AE8/AD8 | AF3: =AH8/AF8 | AH3: =AH8/AG8 | AI3: =AK8/AI8 | AK3: =AK8/AJ8 | AL3: =AN8/AL8 | AN3: =AN8/AM8 | AO3: =AQ8/AO8 | AQ3: =AQ8/AP8 | AR3: =AT8/AR8 | AT3: =AT8/AS8 | AU3: =AW8/AU8 | AW3: =AW8/AV8 | AX3: =AZ8/AX8 | AZ3: =AZ8/AY8 | BA3: =BC8/BA8 | BC3: =BC8/BB8 | BD3: =BF8/BD8 | BF3: =BF8/BE8 | BG3: =BI8/BG8 | BI3: =BI8/BH8
H4: 46023 | K4: 46054 | N4: 46082 | Q4: 46113 | T4: 46143 | W4: 46174 | Z4: 46204 | AC4: 46235 | AF4: 46266 | AI4: 46296 | AL4: 46327 | AO4: 46357 | AR4: Acumulado | AU4: ANO | AX4: 1º TRIMESTRE | BA4: 2º TRIMESTRE | BD4: 3º TRIMESTRE | BG4: 4º TRIMESTRE
H5: 1 | I5: 1 | J5: =MONTH(H4) | K5: 2 | L5: 2 | M5: =MONTH(K4) | N5: 3 | O5: 3 | P5: =MONTH(N4) | Q5: 4 | R5: 4 | S5: =MONTH(Q4) | T5: 5 | U5: 5 | V5: =MONTH(T4) | W5: 6 | X5: 6 | Y5: 6 | Z5: 7 | AA5: 7 | AB5: =MONTH(Z4) | AC5: 8 | AD5: 8 | AE5: =MONTH(AC4) | AF5: 9 | AG5: 9 | AH5: =MONTH(AF4) | AI5: 10 | AJ5: 10 | AK5: =MONTH(AI4) | AL5: 11 | AM5: 11 | AN5: =MONTH(AL4) | AO5: 12 | AP5: 12 | AQ5: =MONTH(AO4)
H6: REAL 25 | I6: ORÇADO | J6: REAL 26 | K6: REAL 25 | L6: ORÇADO | M6: REAL 26 | N6: REAL 25 | O6: ORÇADO | P6: REAL 26 | Q6: REAL 25 | R6: ORÇADO | S6: REAL 26 | T6: REAL 25 | U6: ORÇADO | V6: REAL 26 | W6: REAL 25 | X6: ORÇADO | Y6: REAL 26 | Z6: REAL 25 | AA6: ORÇADO | AB6: REAL 26 | AC6: REAL 25 | AD6: ORÇADO | AE6: REAL 26 | AF6: REAL 25 | AG6: ORÇADO | AH6: REAL 26 | AI6: REAL 25 | AJ6: ORÇADO | AK6: REAL 26 | AL6: REAL 25 | AM6: ORÇADO | AN6: REAL 26 | AO6: REAL 25 | AP6: ORÇADO | AQ6: REAL 26 | AR6: 2025 | AS6: ORÇADO | AT6: REAL 2026 | AU6: 2025 | AV6: ORÇADO | AW6: REAL 2026 | AX6: REAL 25 | AY6: ORÇADO | AZ6: REAL 26 | BA6: REAL 25 | BB6: ORÇADO | BC6: REAL 26 | BD6: REAL 25 | BE6: ORÇADO | BF6: REAL 26 | BG6: REAL 25 | BH6: ORÇADO | BI6: REAL 26
H7: 45658 | I7: 46023 | K7: 45689 | L7: 46054 | N7: 45717 | O7: 46082 | Q7: 45748 | T7: 45778 | W7: 45809 | Z7: 45839 | AC7: 45870 | AF7: 45901 | AI7: 45931 | AL7: 45962 | AO7: 45992
A8: FATURAMENTO BRUTO | C8: PARÂMETROS UTILIZADOS | I8: =SUM(I9:I19) | J8: =SUM(J9:J19) | L8: =SUM(L9:L19) | M8: =SUM(M9:M19)+SUMIFS(Aut_Ajustes_Manuais!$G:$G,Aut_Ajustes_Manuais!$I:$I,DRE!K$4,Aut_Ajustes_Manuais!$F:$F,"FATURAMENTO BRUTO") | O8: =SUM(O9:O19) | P8: =SUM(P9:P19)+SUMIFS(Aut_Ajustes_Manuais!$G:$G,Aut_Ajustes_Manuais!$I:$I,DRE!N$4,Aut_Ajustes_Manuais!$F:$F,"FATURAMENTO BRUTO") | R8: =SUM(R9:R19) | S8: =SUM(S9:S19)+SUMIFS(Aut_Ajustes_Manuais!$G:$G,Aut_Ajustes_Manuais!$I:$I,DRE!Q$4,Aut_Ajustes_Manuais!$F:$F,"FATURAMENTO BRUTO") | U8: =SUM(U9:U19) | V8: =SUM(V9:V19)+SUMIFS(Aut_Ajustes_Manuais!$G:$G,Aut_Ajustes_Manuais!$I:$I,DRE!T$4,Aut_Ajustes_Manuais!$F:$F,"FATURAMENTO BRUTO") | X8: =SUM(X9:X19) | Y8: =SUM(Y9:Y19)+SUMIFS(Aut_Ajustes_Manuais!$G:$G,Aut_Ajustes_Manuais!$I:$I,DRE!W$4,Aut_Ajustes_Manuais!$F:$F,"FATURAMENTO BRUTO") | AA8: =SUM(AA9:AA19) | AB8: =SUM(AB9:AB19)+SUMIFS(Aut_Ajustes_Manuais!$G:$G,Aut_Ajustes_Manuais!$I:$I,DRE!Z$4,Aut_Ajustes_Manuais!$F:$F,"FATURAMENTO BRUTO") | AD8: =SUM(AD9:AD19) | AE8: =SUM(AE9:AE19)+SUMIFS(Aut_Ajustes_Manuais!$G:$G,Aut_Ajustes_Manuais!$I:$I,DRE!AC$4,Aut_Ajustes_Manuais!$F:$F,"FATURAMENTO BRUTO") | AG8: =SUM(AG9:AG19) | AH8: =SUM(AH9:AH19)+SUMIFS(Aut_Ajustes_Manuais!$G:$G,Aut_Ajustes_Manuais!$I:$I,DRE!AF$4,Aut_Ajustes_Manuais!$F:$F,"FATURAMENTO BRUTO") | AJ8: =SUM(AJ9:AJ19) | AK8: =SUM(AK9:AK19)+SUMIFS(Aut_Ajustes_Manuais!$G:$G,Aut_Ajustes_Manuais!$I:$I,DRE!AI$4,Aut_Ajustes_Manuais!$F:$F,"FATURAMENTO BRUTO") | AM8: =SUM(AM9:AM19) | AN8: =SUM(AN9:AN19)+SUMIFS(Aut_Ajustes_Manuais!$G:$G,Aut_Ajustes_Manuais!$I:$I,DRE!AL$4,Aut_Ajustes_Manuais!$F:$F,"FATURAMENTO BRUTO") | AP8: =SUM(AP9:AP19) | AQ8: =SUM(AQ9:AQ19)+SUMIFS(Aut_Ajustes_Manuais!$G:$G,Aut_Ajustes_Manuais!$I:$I,DRE!AO$4,Aut_Ajustes_Manuais!$F:$F,"FATURAMENTO BRUTO") | AR8: =SUM(AR9:AR19) | AS8: =SUM(AS9:AS19) | AT8: =SUM(AT9:AT19) | AU8: =SUM(AU9:AU19) | AV8: =SUM(AV9:AV19) | AW8: =SUM(AW9:AW19) | AX8: =SUM(AX9:AX19) | AY8: =SUM(AY9:AY19) | ... BI8: =SUM(BI9:BI19)
A9: Alimentação | C9: Estim. Mensal | D9: Preencher base de Faturamento A&B&C | I9: =SUMIFS(T_ORCAMENTOS!$E:$E,T_ORCAMENTOS!$C:$C,"Alimentação",T_ORCAMENTOS!$H:$H,"1/2026") | J9: =SUMIFS(Aut_Faturamento_Zig!$F:$F,Aut_Faturamento_Zig!$E:$E,"Alimentos",Aut_Faturamento_Zig!$D:$D,DRE!H$4)-SUMIFS(Aut_Promocoes_Utilizadas!$G:$G,Aut_Promocoes_Utilizadas!$J:$J,DRE!H$4,Aut_Promocoes_Utilizadas!$H:$H,"A",Aut_Promocoes_Utilizadas!$I:$I,"Eventos")-SUMIFS(Aut_Descontos!$I:$I,Aut_Descontos!$L:$L,DRE!H$4)-(SUMIFS(BD_Eventos_Novo!$J:$J,BD_Eventos_Novo!$AB:$AB,DRE!H$4,BD_Eventos_Novo!$G:$G,"Consumação Mínima")*50%)-(SUMIFS(BD_Eventos_Novo!$K:$K,BD_Eventos_Novo!$AB:$AB,DRE!H$4,BD_Eventos_Novo!$G:$G,"Consumação Mínima")*50%)-(SUMIFS(BD_Eventos_Novo!$J:$J,BD_Eventos_Novo!$AB:$AB,DRE!H$4,BD_Eventos_Novo!$G:$G,"Comanda Aberta / Couvert Antecipado")*50%)-(SUMIFS(BD_Eventos_Novo!$K:$K,BD_Eventos_Novo!$AB:$AB,DRE!H$4,BD_Eventos_Novo!$G:$G,"Comanda Aberta / Couvert Antecipado")*50%)+SUMIFS(Aut_Ajustes_Manuais!$G:$G,Aut_Ajustes_Manuais!$I:$I,DRE!H$4,Aut_Ajustes_Manuais!$F:$F,"Alimentação") | L9: =SUMIFS(T_ORCAMENTOS!$E:$E,T_ORCAMENTOS!$C:$C,"Alimentação",T_ORCAMENTOS!$H:$H,"2/2026") | M9: =SUMIFS(Aut_Faturamento_Zig!$F:$F,Aut_Faturamento_Zig!$E:$E,"Alimentos",Aut_Faturamento_Zig!$D:$D,DRE!K$4)-SUMIFS(Aut_Promocoes_Utilizadas!$G:$G,Aut_Promocoes_Utilizadas!$J:$J,DRE!K$4,Aut_Promocoes_Utilizadas!$H:$H,"A",Aut_Promocoes_Utilizadas!$I:$I,"Eventos")-SUMIFS(Aut_Descontos!$I:$I,Aut_Descontos!$L:$L,DRE!K$4)-(SUMIFS(BD_Eventos_Novo!$J:$J,BD_Eventos_Novo!$AB:$AB,DRE!K$4,BD_Eventos_Novo!$G:$G,"Consumação Mínima")*50%)-(SUMIFS(BD_Eventos_Novo!$K:$K,BD_Eventos_Novo!$AB:$AB,DRE!K$4,BD_Eventos_Novo!$G:$G,"Consumação Mínima")*50%)-(SUMIFS(BD_Eventos_Novo!$J:$J,BD_Eventos_Novo!$AB:$AB,DRE!K$4,BD_Eventos_Novo!$G:$G,"Comanda Aberta / Couvert Antecipado")*50%)-(SUMIFS(BD_Eventos_Novo!$K:$K,BD_Eventos_Novo!$AB:$AB,DRE!K$4,BD_Eventos_Novo!$G:$G,"Comanda Aberta / Couvert Antecipado")*50%)+SUMIFS(Aut_Ajustes_Manuais!$G:$G,Aut_Ajustes_Manuais!$I:$I,DRE!K$4,Aut_Ajustes_Manuais!$F:$F,"Alimentação") | O9: =SUMIFS(T_ORCAMENTOS!$E:$E,T_ORCAMENTOS!$C:$C,"Alimentação",T_ORCAMENTOS!$H:$H,"3/2026") | P9: =SUMIFS(Aut_Faturamento_Zig!$F:$F,Aut_Faturamento_Zig!$E:$E,"Alimentos",Aut_Faturamento_Zig!$D:$D,DRE!N$4)-SUMIFS(Aut_Promocoes_Utilizadas!$G:$G,Aut_Promocoes_Utilizadas!$J:$J,DRE!N$4,Aut_Promocoes_Utilizadas!$H:$H,"A",Aut_Promocoes_Utilizadas!$I:$I,"Eventos")-SUMIFS(Aut_Descontos!$I:$I,Aut_Descontos!$L:$L,DRE!N$4)-(SUMIFS(BD_Eventos_Novo!$J:$J,BD_Eventos_Novo!$AB:$AB,DRE!N$4,BD_Eventos_Novo!$G:$G,"Consumação Mínima")*50%)-(SUMIFS(BD_Eventos_Novo!$K:$K,BD_Eventos_Novo!$AB:$AB,DRE!N$4,BD_Eventos_Novo!$G:$G,"Consumação Mínima")*50%)-(SUMIFS(BD_Eventos_Novo!$J:$J,BD_Eventos_Novo!$AB:$AB,DRE!N$4,BD_Eventos_Novo!$G:$G,"Comanda Aberta / Couvert Antecipado")*50%)-(SUMIFS(BD_Eventos_Novo!$K:$K,BD_Eventos_Novo!$AB:$AB,DRE!N$4,BD_Eventos_Novo!$G:$G,"Comanda Aberta / Couvert Antecipado")*50%)+SUMIFS(Aut_Ajustes_Manuais!$G:$G,Aut_Ajustes_Manuais!$I:$I,DRE!N$4,Aut_Ajustes_Manuais!$F:$F,"Alimentação") | R9: =SUMIFS(T_ORCAMENTOS!$E:$E,T_ORCAMENTOS!$C:$C,"Alimentação",T_ORCAMENTOS!$H:$H,"4/2026") | S9: =SUMIFS(Aut_Faturamento_Zig!$F:$F,Aut_Faturamento_Zig!$E:$E,"Alimentos",Aut_Faturamento_Zig!$D:$D,DRE!Q$4)-SUMIFS(Aut_Promocoes_Utilizadas!$G:$G,Aut_Promocoes_Utilizadas!$J:$J,DRE!Q$4,Aut_Promocoes_Utilizadas!$H:$H,"A",Aut_Promocoes_Utilizadas!$I:$I,"Eventos")-SUMIFS(Aut_Descontos!$I:$I,Aut_Descontos!$L:$L,DRE!Q$4)-(SUMIFS(BD_Eventos_Novo!$J:$J,BD_Eventos_Novo!$AB:$AB,DRE!Q$4,BD_Eventos_Novo!$G:$G,"Consumação Mínima")*50%)-(SUMIFS(BD_Eventos_Novo!$K:$K,BD_Eventos_Novo!$AB:$AB,DRE!Q$4,BD_Eventos_Novo!$G:$G,"Consumação Mínima")*50%)-(SUMIFS(BD_Eventos_Novo!$J:$J,BD_Eventos_Novo!$AB:$AB,DRE!Q$4,BD_Eventos_Novo!$G:$G,"Comanda Aberta / Couvert Antecipado")*50%)-(SUMIFS(BD_Eventos_Novo!$K:$K,BD_Eventos_Novo!$AB:$AB,DRE!Q$4,BD_Eventos_Novo!$G:$G,"Comanda Aberta / Couvert Antecipado")*50%)+SUMIFS(Aut_Ajustes_Manuais!$G:$G,Aut_Ajustes_Manuais!$I:$I,DRE!Q$4,Aut_Ajustes_Manuais!$F:$F,"Alimentação") | U9: =SUMIFS(T_ORCAMENTOS!$E:$E,T_ORCAMENTOS!$C:$C,"Alimentação",T_ORCAMENTOS!$H:$H,"5/2026") | V9: =SUMIFS(Aut_Faturamento_Zig!$F:$F,Aut_Faturamento_Zig!$E:$E,"Alimentos",Aut_Faturamento_Zig!$D:$D,DRE!T$4)-SUMIFS(Aut_Promocoes_Utilizadas!$G:$G,Aut_Promocoes_Utilizadas!$J:$J,DRE!T$4,Aut_Promocoes_Utilizadas!$H:$H,"A",Aut_Promocoes_Utilizadas!$I:$I,"Eventos")-SUMIFS(Aut_Descontos!$I:$I,Aut_Descontos!$L:$L,DRE!T$4)-(SUMIFS(BD_Eventos_Novo!$J:$J,BD_Eventos_Novo!$AB:$AB,DRE!T$4,BD_Eventos_Novo!$G:$G,"Consumação Mínima")*50%)-(SUMIFS(BD_Eventos_Novo!$K:$K,BD_Eventos_Novo!$AB:$AB,DRE!T$4,BD_Eventos_Novo!$G:$G,"Consumação Mínima")*50%)-(SUMIFS(BD_Eventos_Novo!$J:$J,BD_Eventos_Novo!$AB:$AB,DRE!T$4,BD_Eventos_Novo!$G:$G,"Comanda Aberta / Couvert Antecipado")*50%)-(SUMIFS(BD_Eventos_Novo!$K:$K,BD_Eventos_Novo!$AB:$AB,DRE!T$4,BD_Eventos_Novo!$G:$G,"Comanda Aberta / Couvert Antecipado")*50%)+SUMIFS(Aut_Ajustes_Manuais!$G:$G,Aut_Ajustes_Manuais!$I:$I,DRE!T$4,Aut_Ajustes_Manuais!$F:$F,"Alimentação") | X9: =SUMIFS(T_ORCAMENTOS!$E:$E,T_ORCAMENTOS!$C:$C,"Alimentação",T_ORCAMENTOS!$H:$H,"6/2026") | Y9: =SUMIFS(Aut_Faturamento_Zig!$F:$F,Aut_Faturamento_Zig!$E:$E,"Alimentos",Aut_Faturamento_Zig!$D:$D,DRE!W$4)-SUMIFS(Aut_Promocoes_Utilizadas!$G:$G,Aut_Promocoes_Utilizadas!$J:$J,DRE!W$4,Aut_Promocoes_Utilizadas!$H:$H,"A",Aut_Promocoes_Utilizadas!$I:$I,"Eventos")-SUMIFS(Aut_Descontos!$I:$I,Aut_Descontos!$L:$L,DRE!W$4)-(SUMIFS(BD_Eventos_Novo!$J:$J,BD_Eventos_Novo!$AB:$AB,DRE!W$4,BD_Eventos_Novo!$G:$G,"Consumação Mínima")*50%)-(SUMIFS(BD_Eventos_Novo!$K:$K,BD_Eventos_Novo!$AB:$AB,DRE!W$4,BD_Eventos_Novo!$G:$G,"Consumação Mínima")*50%)-(SUMIFS(BD_Eventos_Novo!$J:$J,BD_Eventos_Novo!$AB:$AB,DRE!W$4,BD_Eventos_Novo!$G:$G,"Comanda Aberta / Couvert Antecipado")*50%)-(SUMIFS(BD_Eventos_Novo!$K:$K,BD_Eventos_Novo!$AB:$AB,DRE!W$4,BD_Eventos_Novo!$G:$G,"Comanda Aberta / Couvert Antecipado")*50%)+SUMIFS(Aut_Ajustes_Manuais!$G:$G,Aut_Ajustes_Manuais!$I:$I,DRE!W$4,Aut_Ajustes_Manuais!$F:$F,"Alimentação") | AA9: =SUMIFS(T_ORCAMENTOS!$E:$E,T_ORCAMENTOS!$C:$C,"Alimentação",T_ORCAMENTOS!$H:$H,"7/2026") | AB9: =SUMIFS(Aut_Faturamento_Zig!$F:$F,Aut_Faturamento_Zig!$E:$E,"Alimentos",Aut_Faturamento_Zig!$D:$D,DRE!Z$4)-SUMIFS(Aut_Promocoes_Utilizadas!$G:$G,Aut_Promocoes_Utilizadas!$J:$J,DRE!Z$4,Aut_Promocoes_Utilizadas!$H:$H,"A",Aut_Promocoes_Utilizadas!$I:$I,"Eventos")-SUMIFS(Aut_Descontos!$I:$I,Aut_Descontos!$L:$L,DRE!Z$4)-(SUMIFS(BD_Eventos_Novo!$J:$J,BD_Eventos_Novo!$AB:$AB,DRE!Z$4,BD_Eventos_Novo!$G:$G,"Consumação Mínima")*50%)-(SUMIFS(BD_Eventos_Novo!$K:$K,BD_Eventos_Novo!$AB:$AB,DRE!Z$4,BD_Eventos_Novo!$G:$G,"Consumação Mínima")*50%)-(SUMIFS(BD_Eventos_Novo!$J:$J,BD_Eventos_Novo!$AB:$AB,DRE!Z$4,BD_Eventos_Novo!$G:$G,"Comanda Aberta / Couvert Antecipado")*50%)-(SUMIFS(BD_Eventos_Novo!$K:$K,BD_Eventos_Novo!$AB:$AB,DRE!Z$4,BD_Eventos_Novo!$G:$G,"Comanda Aberta / Couvert Antecipado")*50%)+SUMIFS(Aut_Ajustes_Manuais!$G:$G,Aut_Ajustes_Manuais!$I:$I,DRE!Z$4,Aut_Ajustes_Manuais!$F:$F,"Alimentação") | AD9: =SUMIFS(T_ORCAMENTOS!$E:$E,T_ORCAMENTOS!$C:$C,"Alimentação",T_ORCAMENTOS!$H:$H,"8/2026") | AE9: =SUMIFS(Aut_Faturamento_Zig!$F:$F,Aut_Faturamento_Zig!$E:$E,"Alimentos",Aut_Faturamento_Zig!$D:$D,DRE!AC$4)-SUMIFS(Aut_Promocoes_Utilizadas!$G:$G,Aut_Promocoes_Utilizadas!$J:$J,DRE!AC$4,Aut_Promocoes_Utilizadas!$H:$H,"A",Aut_Promocoes_Utilizadas!$I:$I,"Eventos")-SUMIFS(Aut_Descontos!$I:$I,Aut_Descontos!$L:$L,DRE!AC$4)-(SUMIFS(BD_Eventos_Novo!$J:$J,BD_Eventos_Novo!$AB:$AB,DRE!AC$4,BD_Eventos_Novo!$G:$G,"Consumação Mínima")*50%)-(SUMIFS(BD_Eventos_Novo!$K:$K,BD_Eventos_Novo!$AB:$AB,DRE!AC$4,BD_Eventos_Novo!$G:$G,"Consumação Mínima")*50%)-(SUMIFS(BD_Eventos_Novo!$J:$J,BD_Eventos_Novo!$AB:$AB,DRE!AC$4,BD_Eventos_Novo!$G:$G,"Comanda Aberta / Couvert Antecipado")*50%)-(SUMIFS(BD_Eventos_Novo!$K:$K,BD_Eventos_Novo!$AB:$AB,DRE!AC$4,BD_Eventos_Novo!$G:$G,"Comanda Aberta / Couvert Antecipado")*50%)+SUMIFS(Aut_Ajustes_Manuais!$G:$G,Aut_Ajustes_Manuais!$I:$I,DRE!AC$4,Aut_Ajustes_Manuais!$F:$F,"Alimentação") | AG9: =SUMIFS(T_ORCAMENTOS!$E:$E,T_ORCAMENTOS!$C:$C,"Alimentação",T_ORCAMENTOS!$H:$H,"9/2026") | AH9: =SUMIFS(Aut_Faturamento_Zig!$F:$F,Aut_Faturamento_Zig!$E:$E,"Alimentos",Aut_Faturamento_Zig!$D:$D,DRE!AF$4)-SUMIFS(Aut_Promocoes_Utilizadas!$G:$G,Aut_Promocoes_Utilizadas!$J:$J,DRE!AF$4,Aut_Promocoes_Utilizadas!$H:$H,"A",Aut_Promocoes_Utilizadas!$I:$I,"Eventos")-SUMIFS(Aut_Descontos!$I:$I,Aut_Descontos!$L:$L,DRE!AF$4)-(SUMIFS(BD_Eventos_Novo!$J:$J,BD_Eventos_Novo!$AB:$AB,DRE!AF$4,BD_Eventos_Novo!$G:$G,"Consumação Mínima")*50%)-(SUMIFS(BD_Eventos_Novo!$K:$K,BD_Eventos_Novo!$AB:$AB,DRE!AF$4,BD_Eventos_Novo!$G:$G,"Consumação Mínima")*50%)-(SUMIFS(BD_Eventos_Novo!$J:$J,BD_Eventos_Novo!$AB:$AB,DRE!AF$4,BD_Eventos_Novo!$G:$G,"Comanda Aberta / Couvert Antecipado")*50%)-(SUMIFS(BD_Eventos_Novo!$K:$K,BD_Eventos_Novo!$AB:$AB,DRE!AF$4,BD_Eventos_Novo!$G:$G,"Comanda Aberta / Couvert Antecipado")*50%)+SUMIFS(Aut_Ajustes_Manuais!$G:$G,Aut_Ajustes_Manuais!$I:$I,DRE!AF$4,Aut_Ajustes_Manuais!$F:$F,"Alimentação") | AJ9: =SUMIFS(T_ORCAMENTOS!$E:$E,T_ORCAMENTOS!$C:$C,"Alimentação",T_ORCAMENTOS!$H:$H,"10/2026") | AK9: =SUMIFS(Aut_Faturamento_Zig!$F:$F,Aut_Faturamento_Zig!$E:$E,"Alimentos",Aut_Faturamento_Zig!$D:$D,DRE!AI$4)-SUMIFS(Aut_Promocoes_Utilizadas!$G:$G,Aut_Promocoes_Utilizadas!$J:$J,DRE!AI$4,Aut_Promocoes_Utilizadas!$H:$H,"A",Aut_Promocoes_Utilizadas!$I:$I,"Eventos")-SUMIFS(Aut_Descontos!$I:$I,Aut_Descontos!$L:$L,DRE!AI$4)-(SUMIFS(BD_Eventos_Novo!$J:$J,BD_Eventos_Novo!$AB:$AB,DRE!AI$4,BD_Eventos_Novo!$G:$G,"Consumação Mínima")*50%)-(SUMIFS(BD_Eventos_Novo!$K:$K,BD_Eventos_Novo!$AB:$AB,DRE!AI$4,BD_Eventos_Novo!$G:$G,"Consumação Mínima")*50%)-(SUMIFS(BD_Eventos_Novo!$J:$J,BD_Eventos_Novo!$AB:$AB,DRE!AI$4,BD_Eventos_Novo!$G:$G,"Comanda Aberta / Couvert Antecipado")*50%)-(SUMIFS(BD_Eventos_Novo!$K:$K,BD_Eventos_Novo!$AB:$AB,DRE!AI$4,BD_Eventos_Novo!$G:$G,"Comanda Aberta / Couvert Antecipado")*50%)+SUMIFS(Aut_Ajustes_Manuais!$G:$G,Aut_Ajustes_Manuais!$I:$I,DRE!AI$4,Aut_Ajustes_Manuais!$F:$F,"Alimentação") | AM9: =SUMIFS(T_ORCAMENTOS!$E:$E,T_ORCAMENTOS!$C:$C,"Alimentação",T_ORCAMENTOS!$H:$H,"11/2026") | AN9: =SUMIFS(Aut_Faturamento_Zig!$F:$F,Aut_Faturamento_Zig!$E:$E,"Alimentos",Aut_Faturamento_Zig!$D:$D,DRE!AL$4)-SUMIFS(Aut_Promocoes_Utilizadas!$G:$G,Aut_Promocoes_Utilizadas!$J:$J,DRE!AL$4,Aut_Promocoes_Utilizadas!$H:$H,"A",Aut_Promocoes_Utilizadas!$I:$I,"Eventos")-SUMIFS(Aut_Descontos!$I:$I,Aut_Descontos!$L:$L,DRE!AL$4)-(SUMIFS(BD_Eventos_Novo!$J:$J,BD_Eventos_Novo!$AB:$AB,DRE!AL$4,BD_Eventos_Novo!$G:$G,"Consumação Mínima")*50%)-(SUMIFS(BD_Eventos_Novo!$K:$K,BD_Eventos_Novo!$AB:$AB,DRE!AL$4,BD_Eventos_Novo!$G:$G,"Consumação Mínima")*50%)-(SUMIFS(BD_Eventos_Novo!$J:$J,BD_Eventos_Novo!$AB:$AB,DRE!AL$4,BD_Eventos_Novo!$G:$G,"Comanda Aberta / Couvert Antecipado")*50%)-(SUMIFS(BD_Eventos_Novo!$K:$K,BD_Eventos_Novo!$AB:$AB,DRE!AL$4,BD_Eventos_Novo!$G:$G,"Comanda Aberta / Couvert Antecipado")*50%)+SUMIFS(Aut_Ajustes_Manuais!$G:$G,Aut_Ajustes_Manuais!$I:$I,DRE!AL$4,Aut_Ajustes_Manuais!$F:$F,"Alimentação") | AP9: =SUMIFS(T_ORCAMENTOS!$E:$E,T_ORCAMENTOS!$C:$C,"Alimentação",T_ORCAMENTOS!$H:$H,"12/2026") | AQ9: =SUMIFS(Aut_Faturamento_Zig!$F:$F,Aut_Faturamento_Zig!$E:$E,"Alimentos",Aut_Faturamento_Zig!$D:$D,DRE!AO$4)-SUMIFS(Aut_Promocoes_Utilizadas!$G:$G,Aut_Promocoes_Utilizadas!$J:$J,DRE!AO$4,Aut_Promocoes_Utilizadas!$H:$H,"A",Aut_Promocoes_Utilizadas!$I:$I,"Eventos")-SUMIFS(Aut_Descontos!$I:$I,Aut_Descontos!$L:$L,DRE!AO$4)-(SUMIFS(BD_Eventos_Novo!$J:$J,BD_Eventos_Novo!$AB:$AB,DRE!AO$4,BD_Eventos_Novo!$G:$G,"Consumação Mínima")*50%)-(SUMIFS(BD_Eventos_Novo!$K:$K,BD_Eventos_Novo!$AB:$AB,DRE!AO$4,BD_Eventos_Novo!$G:$G,"Consumação Mínima")*50%)-(SUMIFS(BD_Eventos_Novo!$J:$J,BD_Eventos_Novo!$AB:$AB,DRE!AO$4,BD_Eventos_Novo!$G:$G,"Comanda Aberta / Couvert Antecipado")*50%)-(SUMIFS(BD_Eventos_Novo!$K:$K,BD_Eventos_Novo!$AB:$AB,DRE!AO$4,BD_Eventos_Novo!$G:$G,"Comanda Aberta / Couvert Antecipado")*50%)+SUMIFS(Aut_Ajustes_Manuais!$G:$G,Aut_Ajustes_Manuais!$I:$I,DRE!AO$4,Aut_Ajustes_Manuais!$F:$F,"Alimentação") | AR9: =SUMIFS($H9:$AO9,$H$5:$AO$5,"<"&MONTH(TODAY()),$H$6:$AO$6,"REAL 25") | AS9: =SUMIFS($I9:$AP9,$I$5:$AP$5,"<"&MONTH(TODAY()),$I$6:$AP$6,"ORÇADO ") | AT9: =SUMIFS($J9:$AQ9,$J$5:$AQ$5,"<"&MONTH(TODAY()),$J$6:$AQ$6,"REAL 26") | AU9: =SUM(H9,K9,N9,Q9,T9,W9,Z9,AC9,AF9,AI9,AL9,AO9) | AV9: =SUM(I9,L9,O9,R9,U9,X9,AA9,AD9,AG9,AJ9,AM9,AP9) | AW9: =SUM(J9,M9,P9,S9,V9,Y9,AB9,AE9,AH9,AK9,AN9,AQ9) | AX9: =SUM(H9,K9,N9) | AY9: =SUM(I9,L9,O9) | AZ9: =SUM(J9,M9,P9) | BA9: =SUM(Q9,T9,W9) | BB9: =SUM(R9,U9,X9) | BC9: =SUM(S9,V9,Y9) | BD9: =SUM(Z9,AC9,AF9) | BE9: =SUM(AA9,AD9,AG9) | BF9: =SUM(AB9,AE9,AH9) | BG9: =SUM(AI9,AL9,AO9) | BH9: =SUM(AJ9,AM9,AP9) | BI9: =SUM(AK9,AN9,AQ9)
A10: Bebida | C10: Estim. Mensal | D10: Preencher base de Faturamento A&B&C | I10: =SUMIFS(T_ORCAMENTOS!$E:$E,T_ORCAMENTOS!$C:$C,"Bebida",T_ORCAMENTOS!$H:$H,"1/2026") | J10: =SUMIFS(Aut_Faturamento_Zig!$F:$F,Aut_Faturamento_Zig!$E:$E,"Bebidas",Aut_Faturamento_Zig!$D:$D,DRE!H$4)-SUMIFS(Aut_Promocoes_Utilizadas!$G:$G,Aut_Promocoes_Utilizadas!$J:$J,DRE!H$4,Aut_Promocoes_Utilizadas!$H:$H,"B",Aut_Promocoes_Utilizadas!$I:$I,"Eventos")-SUMIFS(Aut_Descontos!$J:$J,Aut_Descontos!$L:$L,DRE!H$4)-(SUMIFS(BD_Eventos_Novo!$J:$J,BD_Eventos_Novo!$AB:$AB,DRE!H$4,BD_Eventos_Novo!$G:$G,"Consumação Mínima")*50%)-(SUMIFS(BD_Eventos_Novo!$K:$K,BD_Eventos_Novo!$AB:$AB,DRE!H$4,BD_Eventos_Novo!$G:$G,"Consumação Mínima")*50%)-(SUMIFS(BD_Eventos_Novo!$J:$J,BD_Eventos_Novo!$AB:$AB,DRE!H$4,BD_Eventos_Novo!$G:$G,"Comanda Aberta / Couvert Antecipado")*50%)-(SUMIFS(BD_Eventos_Novo!$K:$K,BD_Eventos_Novo!$AB:$AB,DRE!H$4,BD_Eventos_Novo!$G:$G,"Comanda Aberta / Couvert Antecipado")*50%)+SUMIFS(Aut_Ajustes_Manuais!$G:$G,Aut_Ajustes_Manuais!$I:$I,DRE!H$4,Aut_Ajustes_Manuais!$F:$F,"Bebida") | L10: =SUMIFS(T_ORCAMENTOS!$E:$E,T_ORCAMENTOS!$C:$C,"Bebida",T_ORCAMENTOS!$H:$H,"2/2026") | M10: =SUMIFS(Aut_Faturamento_Zig!$F:$F,Aut_Faturamento_Zig!$E:$E,"Bebidas",Aut_Faturamento_Zig!$D:$D,DRE!K$4)-SUMIFS(Aut_Promocoes_Utilizadas!$G:$G,Aut_Promocoes_Utilizadas!$J:$J,DRE!K$4,Aut_Promocoes_Utilizadas!$H:$H,"B",Aut_Promocoes_Utilizadas!$I:$I,"Eventos")-SUMIFS(Aut_Descontos!$J:$J,Aut_Descontos!$L:$L,DRE!K$4)-(SUMIFS(BD_Eventos_Novo!$J:$J,BD_Eventos_Novo!$AB:$AB,DRE!K$4,BD_Eventos_Novo!$G:$G,"Consumação Mínima")*50%)-(SUMIFS(BD_Eventos_Novo!$K:$K,BD_Eventos_Novo!$AB:$AB,DRE!K$4,BD_Eventos_Novo!$G:$G,"Consumação Mínima")*50%)-(SUMIFS(BD_Eventos_Novo!$J:$J,BD_Eventos_Novo!$AB:$AB,DRE!K$4,BD_Eventos_Novo!$G:$G,"Comanda Aberta / Couvert Antecipado")*50%)-(SUMIFS(BD_Eventos_Novo!$K:$K,BD_Eventos_Novo!$AB:$AB,DRE!K$4,BD_Eventos_Novo!$G:$G,"Comanda Aberta / Couvert Antecipado")*50%)+SUMIFS(Aut_Ajustes_Manuais!$G:$G,Aut_Ajustes_Manuais!$I:$I,DRE!K$4,Aut_Ajustes_Manuais!$F:$F,"Bebida") | O10: =SUMIFS(T_ORCAMENTOS!$E:$E,T_ORCAMENTOS!$C:$C,"Bebida",T_ORCAMENTOS!$H:$H,"3/2026") | P10: =SUMIFS(Aut_Faturamento_Zig!$F:$F,Aut_Faturamento_Zig!$E:$E,"Bebidas",Aut_Faturamento_Zig!$D:$D,DRE!N$4)-SUMIFS(Aut_Promocoes_Utilizadas!$G:$G,Aut_Promocoes_Utilizadas!$J:$J,DRE!N$4,Aut_Promocoes_Utilizadas!$H:$H,"B",Aut_Promocoes_Utilizadas!$I:$I,"Eventos")-SUMIFS(Aut_Descontos!$J:$J,Aut_Descontos!$L:$L,DRE!N$4)-(SUMIFS(BD_Eventos_Novo!$J:$J,BD_Eventos_Novo!$AB:$AB,DRE!N$4,BD_Eventos_Novo!$G:$G,"Consumação Mínima")*50%)-(SUMIFS(BD_Eventos_Novo!$K:$K,BD_Eventos_Novo!$AB:$AB,DRE!N$4,BD_Eventos_Novo!$G:$G,"Consumação Mínima")*50%)-(SUMIFS(BD_Eventos_Novo!$J:$J,BD_Eventos_Novo!$AB:$AB,DRE!N$4,BD_Eventos_Novo!$G:$G,"Comanda Aberta / Couvert Antecipado")*50%)-(SUMIFS(BD_Eventos_Novo!$K:$K,BD_Eventos_Novo!$AB:$AB,DRE!N$4,BD_Eventos_Novo!$G:$G,"Comanda Aberta / Couvert Antecipado")*50%)+SUMIFS(Aut_Ajustes_Manuais!$G:$G,Aut_Ajustes_Manuais!$I:$I,DRE!N$4,Aut_Ajustes_Manuais!$F:$F,"Bebida") | R10: =SUMIFS(T_ORCAMENTOS!$E:$E,T_ORCAMENTOS!$C:$C,"Bebida",T_ORCAMENTOS!$H:$H,"4/2026") | S10: =SUMIFS(Aut_Faturamento_Zig!$F:$F,Aut_Faturamento_Zig!$E:$E,"Bebidas",Aut_Faturamento_Zig!$D:$D,DRE!Q$4)-SUMIFS(Aut_Promocoes_Utilizadas!$G:$G,Aut_Promocoes_Utilizadas!$J:$J,DRE!Q$4,Aut_Promocoes_Utilizadas!$H:$H,"B",Aut_Promocoes_Utilizadas!$I:$I,"Eventos")-SUMIFS(Aut_Descontos!$J:$J,Aut_Descontos!$L:$L,DRE!Q$4)-(SUMIFS(BD_Eventos_Novo!$J:$J,BD_Eventos_Novo!$AB:$AB,DRE!Q$4,BD_Eventos_Novo!$G:$G,"Consumação Mínima")*50%)-(SUMIFS(BD_Eventos_Novo!$K:$K,BD_Eventos_Novo!$AB:$AB,DRE!Q$4,BD_Eventos_Novo!$G:$G,"Consumação Mínima")*50%)-(SUMIFS(BD_Eventos_Novo!$J:$J,BD_Eventos_Novo!$AB:$AB,DRE!Q$4,BD_Eventos_Novo!$G:$G,"Comanda Aberta / Couvert Antecipado")*50%)-(SUMIFS(BD_Eventos_Novo!$K:$K,BD_Eventos_Novo!$AB:$AB,DRE!Q$4,BD_Eventos_Novo!$G:$G,"Comanda Aberta / Couvert Antecipado")*50%)+SUMIFS(Aut_Ajustes_Manuais!$G:$G,Aut_Ajustes_Manuais!$I:$I,DRE!Q$4,Aut_Ajustes_Manuais!$F:$F,"Bebida") | U10: =SUMIFS(T_ORCAMENTOS!$E:$E,T_ORCAMENTOS!$C:$C,"Bebida",T_ORCAMENTOS!$H:$H,"5/2026") | V10: =SUMIFS(Aut_Faturamento_Zig!$F:$F,Aut_Faturamento_Zig!$E:$E,"Bebidas",Aut_Faturamento_Zig!$D:$D,DRE!T$4)-SUMIFS(Aut_Promocoes_Utilizadas!$G:$G,Aut_Promocoes_Utilizadas!$J:$J,DRE!T$4,Aut_Promocoes_Utilizadas!$H:$H,"B",Aut_Promocoes_Utilizadas!$I:$I,"Eventos")-SUMIFS(Aut_Descontos!$J:$J,Aut_Descontos!$L:$L,DRE!T$4)-(SUMIFS(BD_Eventos_Novo!$J:$J,BD_Eventos_Novo!$AB:$AB,DRE!T$4,BD_Eventos_Novo!$G:$G,"Consumação Mínima")*50%)-(SUMIFS(BD_Eventos_Novo!$K:$K,BD_Eventos_Novo!$AB:$AB,DRE!T$4,BD_Eventos_Novo!$G:$G,"Consumação Mínima")*50%)-(SUMIFS(BD_Eventos_Novo!$J:$J,BD_Eventos_Novo!$AB:$AB,DRE!T$4,BD_Eventos_Novo!$G:$G,"Comanda Aberta / Couvert Antecipado")*50%)-(SUMIFS(BD_Eventos_Novo!$K:$K,BD_Eventos_Novo!$AB:$AB,DRE!T$4,BD_Eventos_Novo!$G:$G,"Comanda Aberta / Couvert Antecipado")*50%)+SUMIFS(Aut_Ajustes_Manuais!$G:$G,Aut_Ajustes_Manuais!$I:$I,DRE!T$4,Aut_Ajustes_Manuais!$F:$F,"Bebida") | X10: =SUMIFS(T_ORCAMENTOS!$E:$E,T_ORCAMENTOS!$C:$C,"Bebida",T_ORCAMENTOS!$H:$H,"6/2026") | Y10: =SUMIFS(Aut_Faturamento_Zig!$F:$F,Aut_Faturamento_Zig!$E:$E,"Bebidas",Aut_Faturamento_Zig!$D:$D,DRE!W$4)-SUMIFS(Aut_Promocoes_Utilizadas!$G:$G,Aut_Promocoes_Utilizadas!$J:$J,DRE!W$4,Aut_Promocoes_Utilizadas!$H:$H,"B",Aut_Promocoes_Utilizadas!$I:$I,"Eventos")-SUMIFS(Aut_Descontos!$J:$J,Aut_Descontos!$L:$L,DRE!W$4)-(SUMIFS(BD_Eventos_Novo!$J:$J,BD_Eventos_Novo!$AB:$AB,DRE!W$4,BD_Eventos_Novo!$G:$G,"Consumação Mínima")*50%)-(SUMIFS(BD_Eventos_Novo!$K:$K,BD_Eventos_Novo!$AB:$AB,DRE!W$4,BD_Eventos_Novo!$G:$G,"Consumação Mínima")*50%)-(SUMIFS(BD_Eventos_Novo!$J:$J,BD_Eventos_Novo!$AB:$AB,DRE!W$4,BD_Eventos_Novo!$G:$G,"Comanda Aberta / Couvert Antecipado")*50%)-(SUMIFS(BD_Eventos_Novo!$K:$K,BD_Eventos_Novo!$AB:$AB,DRE!W$4,BD_Eventos_Novo!$G:$G,"Comanda Aberta / Couvert Antecipado")*50%)+SUMIFS(Aut_Ajustes_Manuais!$G:$G,Aut_Ajustes_Manuais!$I:$I,DRE!W$4,Aut_Ajustes_Manuais!$F:$F,"Bebida") | AA10: =SUMIFS(T_ORCAMENTOS!$E:$E,T_ORCAMENTOS!$C:$C,"Bebida",T_ORCAMENTOS!$H:$H,"7/2026") | AB10: =SUMIFS(Aut_Faturamento_Zig!$F:$F,Aut_Faturamento_Zig!$E:$E,"Bebidas",Aut_Faturamento_Zig!$D:$D,DRE!Z$4)-SUMIFS(Aut_Promocoes_Utilizadas!$G:$G,Aut_Promocoes_Utilizadas!$J:$J,DRE!Z$4,Aut_Promocoes_Utilizadas!$H:$H,"B",Aut_Promocoes_Utilizadas!$I:$I,"Eventos")-SUMIFS(Aut_Descontos!$J:$J,Aut_Descontos!$L:$L,DRE!Z$4)-(SUMIFS(BD_Eventos_Novo!$J:$J,BD_Eventos_Novo!$AB:$AB,DRE!Z$4,BD_Eventos_Novo!$G:$G,"Consumação Mínima")*50%)-(SUMIFS(BD_Eventos_Novo!$K:$K,BD_Eventos_Novo!$AB:$AB,DRE!Z$4,BD_Eventos_Novo!$G:$G,"Consumação Mínima")*50%)-(SUMIFS(BD_Eventos_Novo!$J:$J,BD_Eventos_Novo!$AB:$AB,DRE!Z$4,BD_Eventos_Novo!$G:$G,"Comanda Aberta / Couvert Antecipado")*50%)-(SUMIFS(BD_Eventos_Novo!$K:$K,BD_Eventos_Novo!$AB:$AB,DRE!Z$4,BD_Eventos_Novo!$G:$G,"Comanda Aberta / Couvert Antecipado")*50%)+SUMIFS(Aut_Ajustes_Manuais!$G:$G,Aut_Ajustes_Manuais!$I:$I,DRE!Z$4,Aut_Ajustes_Manuais!$F:$F,"Bebida") | AD10: =SUMIFS(T_ORCAMENTOS!$E:$E,T_ORCAMENTOS!$C:$C,"Bebida",T_ORCAMENTOS!$H:$H,"8/2026") | AE10: =SUMIFS(Aut_Faturamento_Zig!$F:$F,Aut_Faturamento_Zig!$E:$E,"Bebidas",Aut_Faturamento_Zig!$D:$D,DRE!AC$4)-SUMIFS(Aut_Promocoes_Utilizadas!$G:$G,Aut_Promocoes_Utilizadas!$J:$J,DRE!AC$4,Aut_Promocoes_Utilizadas!$H:$H,"B",Aut_Promocoes_Utilizadas!$I:$I,"Eventos")-SUMIFS(Aut_Descontos!$J:$J,Aut_Descontos!$L:$L,DRE!AC$4)-(SUMIFS(BD_Eventos_Novo!$J:$J,BD_Eventos_Novo!$AB:$AB,DRE!AC$4,BD_Eventos_Novo!$G:$G,"Consumação Mínima")*50%)-(SUMIFS(BD_Eventos_Novo!$K:$K,BD_Eventos_Novo!$AB:$AB,DRE!AC$4,BD_Eventos_Novo!$G:$G,"Consumação Mínima")*50%)-(SUMIFS(BD_Eventos_Novo!$J:$J,BD_Eventos_Novo!$AB:$AB,DRE!AC$4,BD_Eventos_Novo!$G:$G,"Comanda Aberta / Couvert Antecipado")*50%)-(SUMIFS(BD_Eventos_Novo!$K:$K,BD_Eventos_Novo!$AB:$AB,DRE!AC$4,BD_Eventos_Novo!$G:$G,"Comanda Aberta / Couvert Antecipado")*50%)+SUMIFS(Aut_Ajustes_Manuais!$G:$G,Aut_Ajustes_Manuais!$I:$I,DRE!AC$4,Aut_Ajustes_Manuais!$F:$F,"Bebida") | AG10: =SUMIFS(T_ORCAMENTOS!$E:$E,T_ORCAMENTOS!$C:$C,"Bebida",T_ORCAMENTOS!$H:$H,"9/2026") | AH10: =SUMIFS(Aut_Faturamento_Zig!$F:$F,Aut_Faturamento_Zig!$E:$E,"Bebidas",Aut_Faturamento_Zig!$D:$D,DRE!AF$4)-SUMIFS(Aut_Promocoes_Utilizadas!$G:$G,Aut_Promocoes_Utilizadas!$J:$J,DRE!AF$4,Aut_Promocoes_Utilizadas!$H:$H,"B",Aut_Promocoes_Utilizadas!$I:$I,"Eventos")-SUMIFS(Aut_Descontos!$J:$J,Aut_Descontos!$L:$L,DRE!AF$4)-(SUMIFS(BD_Eventos_Novo!$J:$J,BD_Eventos_Novo!$AB:$AB,DRE!AF$4,BD_Eventos_Novo!$G:$G,"Consumação Mínima")*50%)-(SUMIFS(BD_Eventos_Novo!$K:$K,BD_Eventos_Novo!$AB:$AB,DRE!AF$4,BD_Eventos_Novo!$G:$G,"Consumação Mínima")*50%)-(SUMIFS(BD_Eventos_Novo!$J:$J,BD_Eventos_Novo!$AB:$AB,DRE!AF$4,BD_Eventos_Novo!$G:$G,"Comanda Aberta / Couvert Antecipado")*50%)-(SUMIFS(BD_Eventos_Novo!$K:$K,BD_Eventos_Novo!$AB:$AB,DRE!AF$4,BD_Eventos_Novo!$G:$G,"Comanda Aberta / Couvert Antecipado")*50%)+SUMIFS(Aut_Ajustes_Manuais!$G:$G,Aut_Ajustes_Manuais!$I:$I,DRE!AF$4,Aut_Ajustes_Manuais!$F:$F,"Bebida") | AJ10: =SUMIFS(T_ORCAMENTOS!$E:$E,T_ORCAMENTOS!$C:$C,"Bebida",T_ORCAMENTOS!$H:$H,"10/2026") | AK10: =SUMIFS(Aut_Faturamento_Zig!$F:$F,Aut_Faturamento_Zig!$E:$E,"Bebidas",Aut_Faturamento_Zig!$D:$D,DRE!AI$4)-SUMIFS(Aut_Promocoes_Utilizadas!$G:$G,Aut_Promocoes_Utilizadas!$J:$J,DRE!AI$4,Aut_Promocoes_Utilizadas!$H:$H,"B",Aut_Promocoes_Utilizadas!$I:$I,"Eventos")-SUMIFS(Aut_Descontos!$J:$J,Aut_Descontos!$L:$L,DRE!AI$4)-(SUMIFS(BD_Eventos_Novo!$J:$J,BD_Eventos_Novo!$AB:$AB,DRE!AI$4,BD_Eventos_Novo!$G:$G,"Consumação Mínima")*50%)-(SUMIFS(BD_Eventos_Novo!$K:$K,BD_Eventos_Novo!$AB:$AB,DRE!AI$4,BD_Eventos_Novo!$G:$G,"Consumação Mínima")*50%)-(SUMIFS(BD_Eventos_Novo!$J:$J,BD_Eventos_Novo!$AB:$AB,DRE!AI$4,BD_Eventos_Novo!$G:$G,"Comanda Aberta / Couvert Antecipado")*50%)-(SUMIFS(BD_Eventos_Novo!$K:$K,BD_Eventos_Novo!$AB:$AB,DRE!AI$4,BD_Eventos_Novo!$G:$G,"Comanda Aberta / Couvert Antecipado")*50%)+SUMIFS(Aut_Ajustes_Manuais!$G:$G,Aut_Ajustes_Manuais!$I:$I,DRE!AI$4,Aut_Ajustes_Manuais!$F:$F,"Bebida") | AM10: =SUMIFS(T_ORCAMENTOS!$E:$E,T_ORCAMENTOS!$C:$C,"Bebida",T_ORCAMENTOS!$H:$H,"11/2026") | AN10: =SUMIFS(Aut_Faturamento_Zig!$F:$F,Aut_Faturamento_Zig!$E:$E,"Bebidas",Aut_Faturamento_Zig!$D:$D,DRE!AL$4)-SUMIFS(Aut_Promocoes_Utilizadas!$G:$G,Aut_Promocoes_Utilizadas!$J:$J,DRE!AL$4,Aut_Promocoes_Utilizadas!$H:$H,"B",Aut_Promocoes_Utilizadas!$I:$I,"Eventos")-SUMIFS(Aut_Descontos!$J:$J,Aut_Descontos!$L:$L,DRE!AL$4)-(SUMIFS(BD_Eventos_Novo!$J:$J,BD_Eventos_Novo!$AB:$AB,DRE!AL$4,BD_Eventos_Novo!$G:$G,"Consumação Mínima")*50%)-(SUMIFS(BD_Eventos_Novo!$K:$K,BD_Eventos_Novo!$AB:$AB,DRE!AL$4,BD_Eventos_Novo!$G:$G,"Consumação Mínima")*50%)-(SUMIFS(BD_Eventos_Novo!$J:$J,BD_Eventos_Novo!$AB:$AB,DRE!AL$4,BD_Eventos_Novo!$G:$G,"Comanda Aberta / Couvert Antecipado")*50%)-(SUMIFS(BD_Eventos_Novo!$K:$K,BD_Eventos_Novo!$AB:$AB,DRE!AL$4,BD_Eventos_Novo!$G:$G,"Comanda Aberta / Couvert Antecipado")*50%)+SUMIFS(Aut_Ajustes_Manuais!$G:$G,Aut_Ajustes_Manuais!$I:$I,DRE!AL$4,Aut_Ajustes_Manuais!$F:$F,"Bebida") | AP10: =SUMIFS(T_ORCAMENTOS!$E:$E,T_ORCAMENTOS!$C:$C,"Bebida",T_ORCAMENTOS!$H:$H,"12/2026") | AQ10: =SUMIFS(Aut_Faturamento_Zig!$F:$F,Aut_Faturamento_Zig!$E:$E,"Bebidas",Aut_Faturamento_Zig!$D:$D,DRE!AO$4)-SUMIFS(Aut_Promocoes_Utilizadas!$G:$G,Aut_Promocoes_Utilizadas!$J:$J,DRE!AO$4,Aut_Promocoes_Utilizadas!$H:$H,"B",Aut_Promocoes_Utilizadas!$I:$I,"Eventos")-SUMIFS(Aut_Descontos!$J:$J,Aut_Descontos!$L:$L,DRE!AO$4)-(SUMIFS(BD_Eventos_Novo!$J:$J,BD_Eventos_Novo!$AB:$AB,DRE!AO$4,BD_Eventos_Novo!$G:$G,"Consumação Mínima")*50%)-(SUMIFS(BD_Eventos_Novo!$K:$K,BD_Eventos_Novo!$AB:$AB,DRE!AO$4,BD_Eventos_Novo!$G:$G,"Consumação Mínima")*50%)-(SUMIFS(BD_Eventos_Novo!$J:$J,BD_Eventos_Novo!$AB:$AB,DRE!AO$4,BD_Eventos_Novo!$G:$G,"Comanda Aberta / Couvert Antecipado")*50%)-(SUMIFS(BD_Eventos_Novo!$K:$K,BD_Eventos_Novo!$AB:$AB,DRE!AO$4,BD_Eventos_Novo!$G:$G,"Comanda Aberta / Couvert Antecipado")*50%)+SUMIFS(Aut_Ajustes_Manuais!$G:$G,Aut_Ajustes_Manuais!$I:$I,DRE!AO$4,Aut_Ajustes_Manuais!$F:$F,"Bebida") | AR10: =SUMIFS($H10:$AO10,$H$5:$AO$5,"<"&MONTH(TODAY()),$H$6:$AO$6,"REAL 25") | AS10: =SUMIFS($I10:$AP10,$I$5:$AP$5,"<"&MONTH(TODAY()),$I$6:$AP$6,"ORÇADO ") | AT10: =SUMIFS($J10:$AQ10,$J$5:$AQ$5,"<"&MONTH(TODAY()),$J$6:$AQ$6,"REAL 26") | AU10: =SUM(H10,K10,N10,Q10,T10,W10,Z10,AC10,AF10,AI10,AL10,AO10) | AV10: =SUM(I10,L10,O10,R10,U10,X10,AA10,AD10,AG10,AJ10,AM10,AP10) | AW10: =SUM(J10,M10,P10,S10,V10,Y10,AB10,AE10,AH10,AK10,AN10,AQ10) | AX10: =SUM(H10,K10,N10) | AY10: =SUM(I10,L10,O10) | AZ10: =SUM(J10,M10,P10) | BA10: =SUM(Q10,T10,W10) | BB10: =SUM(R10,U10,X10) | BC10: =SUM(S10,V10,Y10) | BD10: =SUM(Z10,AC10,AF10) | BE10: =SUM(AA10,AD10,AG10) | BF10: =SUM(AB10,AE10,AH10) | BG10: =SUM(AI10,AL10,AO10) | BH10: =SUM(AJ10,AM10,AP10) | BI10: =SUM(AK10,AN10,AQ10)
A11: Artístico (couvert/shows) | C11: Estim. Mensal | D11: Preencher base de Faturamento A&B&C | I11: =SUMIFS(T_ORCAMENTOS!$E:$E,T_ORCAMENTOS!$C:$C,"Artístico (couvert/shows)",T_ORCAMENTOS!$H:$H,"1/2026") | J11: =SUMIFS(Aut_Faturamento_Zig!$F:$F,Aut_Faturamento_Zig!$E:$E,"Couvert",Aut_Faturamento_Zig!$D:$D,DRE!H$4)+SUMIFS(Aut_Ajustes_Manuais!$G:$G,Aut_Ajustes_Manuais!$I:$I,DRE!H$4,Aut_Ajustes_Manuais!$F:$F,"Artístico (couvert/shows)") | L11: =SUMIFS(T_ORCAMENTOS!$E:$E,T_ORCAMENTOS!$C:$C,"Artístico (couvert/shows)",T_ORCAMENTOS!$H:$H,"2/2026") | M11: =SUMIFS(Aut_Faturamento_Zig!$F:$F,Aut_Faturamento_Zig!$E:$E,"Couvert",Aut_Faturamento_Zig!$D:$D,DRE!K$4)+SUMIFS(Aut_Ajustes_Manuais!$G:$G,Aut_Ajustes_Manuais!$I:$I,DRE!K$4,Aut_Ajustes_Manuais!$F:$F,"Artístico (couvert/shows)") | O11: =SUMIFS(T_ORCAMENTOS!$E:$E,T_ORCAMENTOS!$C:$C,"Artístico (couvert/shows)",T_ORCAMENTOS!$H:$H,"3/2026") | P11: =SUMIFS(Aut_Faturamento_Zig!$F:$F,Aut_Faturamento_Zig!$E:$E,"Couvert",Aut_Faturamento_Zig!$D:$D,DRE!N$4)+SUMIFS(Aut_Ajustes_Manuais!$G:$G,Aut_Ajustes_Manuais!$I:$I,DRE!N$4,Aut_Ajustes_Manuais!$F:$F,"Artístico (couvert/shows)") | R11: =SUMIFS(T_ORCAMENTOS!$E:$E,T_ORCAMENTOS!$C:$C,"Artístico (couvert/shows)",T_ORCAMENTOS!$H:$H,"4/2026") | S11: =SUMIFS(Aut_Faturamento_Zig!$F:$F,Aut_Faturamento_Zig!$E:$E,"Couvert",Aut_Faturamento_Zig!$D:$D,DRE!Q$4)+SUMIFS(Aut_Ajustes_Manuais!$G:$G,Aut_Ajustes_Manuais!$I:$I,DRE!Q$4,Aut_Ajustes_Manuais!$F:$F,"Artístico (couvert/shows)") | U11: =SUMIFS(T_ORCAMENTOS!$E:$E,T_ORCAMENTOS!$C:$C,"Artístico (couvert/shows)",T_ORCAMENTOS!$H:$H,"5/2026") | V11: =SUMIFS(Aut_Faturamento_Zig!$F:$F,Aut_Faturamento_Zig!$E:$E,"Couvert",Aut_Faturamento_Zig!$D:$D,DRE!T$4)+SUMIFS(Aut_Ajustes_Manuais!$G:$G,Aut_Ajustes_Manuais!$I:$I,DRE!T$4,Aut_Ajustes_Manuais!$F:$F,"Artístico (couvert/shows)") | X11: =SUMIFS(T_ORCAMENTOS!$E:$E,T_ORCAMENTOS!$C:$C,"Artístico (couvert/shows)",T_ORCAMENTOS!$H:$H,"6/2026") | Y11: =SUMIFS(Aut_Faturamento_Zig!$F:$F,Aut_Faturamento_Zig!$E:$E,"Couvert",Aut_Faturamento_Zig!$D:$D,DRE!W$4)+SUMIFS(Aut_Ajustes_Manuais!$G:$G,Aut_Ajustes_Manuais!$I:$I,DRE!W$4,Aut_Ajustes_Manuais!$F:$F,"Artístico (couvert/shows)") | AA11: =SUMIFS(T_ORCAMENTOS!$E:$E,T_ORCAMENTOS!$C:$C,"Artístico (couvert/shows)",T_ORCAMENTOS!$H:$H,"7/2026") | AB11: =SUMIFS(Aut_Faturamento_Zig!$F:$F,Aut_Faturamento_Zig!$E:$E,"Couvert",Aut_Faturamento_Zig!$D:$D,DRE!Z$4)+SUMIFS(Aut_Ajustes_Manuais!$G:$G,Aut_Ajustes_Manuais!$I:$I,DRE!Z$4,Aut_Ajustes_Manuais!$F:$F,"Artístico (couvert/shows)") | AD11: =SUMIFS(T_ORCAMENTOS!$E:$E,T_ORCAMENTOS!$C:$C,"Artístico (couvert/shows)",T_ORCAMENTOS!$H:$H,"8/2026") | AE11: =SUMIFS(Aut_Faturamento_Zig!$F:$F,Aut_Faturamento_Zig!$E:$E,"Couvert",Aut_Faturamento_Zig!$D:$D,DRE!AC$4)+SUMIFS(Aut_Ajustes_Manuais!$G:$G,Aut_Ajustes_Manuais!$I:$I,DRE!AC$4,Aut_Ajustes_Manuais!$F:$F,"Artístico (couvert/shows)") | AG11: =SUMIFS(T_ORCAMENTOS!$E:$E,T_ORCAMENTOS!$C:$C,"Artístico (couvert/shows)",T_ORCAMENTOS!$H:$H,"9/2026") | AH11: =SUMIFS(Aut_Faturamento_Zig!$F:$F,Aut_Faturamento_Zig!$E:$E,"Couvert",Aut_Faturamento_Zig!$D:$D,DRE!AF$4)+SUMIFS(Aut_Ajustes_Manuais!$G:$G,Aut_Ajustes_Manuais!$I:$I,DRE!AF$4,Aut_Ajustes_Manuais!$F:$F,"Artístico (couvert/shows)") | AJ11: =SUMIFS(T_ORCAMENTOS!$E:$E,T_ORCAMENTOS!$C:$C,"Artístico (couvert/shows)",T_ORCAMENTOS!$H:$H,"10/2026") | AK11: =SUMIFS(Aut_Faturamento_Zig!$F:$F,Aut_Faturamento_Zig!$E:$E,"Couvert",Aut_Faturamento_Zig!$D:$D,DRE!AI$4)+SUMIFS(Aut_Ajustes_Manuais!$G:$G,Aut_Ajustes_Manuais!$I:$I,DRE!AI$4,Aut_Ajustes_Manuais!$F:$F,"Artístico (couvert/shows)") | AM11: =SUMIFS(T_ORCAMENTOS!$E:$E,T_ORCAMENTOS!$C:$C,"Artístico (couvert/shows)",T_ORCAMENTOS!$H:$H,"11/2026") | AN11: =SUMIFS(Aut_Faturamento_Zig!$F:$F,Aut_Faturamento_Zig!$E:$E,"Couvert",Aut_Faturamento_Zig!$D:$D,DRE!AL$4)+SUMIFS(Aut_Ajustes_Manuais!$G:$G,Aut_Ajustes_Manuais!$I:$I,DRE!AL$4,Aut_Ajustes_Manuais!$F:$F,"Artístico (couvert/shows)") | AP11: =SUMIFS(T_ORCAMENTOS!$E:$E,T_ORCAMENTOS!$C:$C,"Artístico (couvert/shows)",T_ORCAMENTOS!$H:$H,"12/2026") | AQ11: =SUMIFS(Aut_Faturamento_Zig!$F:$F,Aut_Faturamento_Zig!$E:$E,"Couvert",Aut_Faturamento_Zig!$D:$D,DRE!AO$4)+SUMIFS(Aut_Ajustes_Manuais!$G:$G,Aut_Ajustes_Manuais!$I:$I,DRE!AO$4,Aut_Ajustes_Manuais!$F:$F,"Artístico (couvert/shows)") | AR11: =SUMIFS($H11:$AO11,$H$5:$AO$5,"<"&MONTH(TODAY()),$H$6:$AO$6,"REAL 25") | AS11: =SUMIFS($I11:$AP11,$I$5:$AP$5,"<"&MONTH(TODAY()),$I$6:$AP$6,"ORÇADO ") | AT11: =SUMIFS($J11:$AQ11,$J$5:$AQ$5,"<"&MONTH(TODAY()),$J$6:$AQ$6,"REAL 26") | AU11: =SUM(H11,K11,N11,Q11,T11,W11,Z11,AC11,AF11,AI11,AL11,AO11) | AV11: =SUM(I11,L11,O11,R11,U11,X11,AA11,AD11,AG11,AJ11,AM11,AP11) | AW11: =SUM(J11,M11,P11,S11,V11,Y11,AB11,AE11,AH11,AK11,AN11,AQ11) | AX11: =SUM(H11,K11,N11) | AY11: =SUM(I11,L11,O11) | AZ11: =SUM(J11,M11,P11) | BA11: =SUM(Q11,T11,W11) | BB11: =SUM(R11,U11,X11) | BC11: =SUM(S11,V11,Y11) | BD11: =SUM(Z11,AC11,AF11) | BE11: =SUM(AA11,AD11,AG11) | BF11: =SUM(AB11,AE11,AH11) | BG11: =SUM(AI11,AL11,AO11) | BH11: =SUM(AJ11,AM11,AP11) | BI11: =SUM(AK11,AN11,AQ11)
A12: Gifts | C12: Estim. Mensal | D12: Vendas Lojinha | I12: =SUMIFS(T_ORCAMENTOS!$E:$E,T_ORCAMENTOS!$C:$C,"Gifts",T_ORCAMENTOS!$H:$H,"1/2026") | J12: =SUMIFS(Aut_Faturamento_Zig!$F:$F,Aut_Faturamento_Zig!$E:$E,"Gifts",Aut_Faturamento_Zig!$D:$D,DRE!H$4)+SUMIFS(Aut_Receitas_Extraord!$L:$L,Aut_Receitas_Extraord!$U:$U,DRE!H$4,Aut_Receitas_Extraord!$D:$D,"Lojinha")+SUMIFS(Aut_Ajustes_Manuais!$G:$G,Aut_Ajustes_Manuais!$I:$I,DRE!H$4,Aut_Ajustes_Manuais!$F:$F,"Gifts") | L12: =SUMIFS(T_ORCAMENTOS!$E:$E,T_ORCAMENTOS!$C:$C,"Gifts",T_ORCAMENTOS!$H:$H,"2/2026") | M12: =SUMIFS(Aut_Faturamento_Zig!$F:$F,Aut_Faturamento_Zig!$E:$E,"Gifts",Aut_Faturamento_Zig!$D:$D,DRE!K$4)+SUMIFS(Aut_Receitas_Extraord!$L:$L,Aut_Receitas_Extraord!$U:$U,DRE!K$4,Aut_Receitas_Extraord!$D:$D,"Lojinha")+SUMIFS(Aut_Ajustes_Manuais!$G:$G,Aut_Ajustes_Manuais!$I:$I,DRE!K$4,Aut_Ajustes_Manuais!$F:$F,"Gifts") | O12: =SUMIFS(T_ORCAMENTOS!$E:$E,T_ORCAMENTOS!$C:$C,"Gifts",T_ORCAMENTOS!$H:$H,"3/2026") | P12: =SUMIFS(Aut_Faturamento_Zig!$F:$F,Aut_Faturamento_Zig!$E:$E,"Gifts",Aut_Faturamento_Zig!$D:$D,DRE!N$4)+SUMIFS(Aut_Receitas_Extraord!$L:$L,Aut_Receitas_Extraord!$U:$U,DRE!N$4,Aut_Receitas_Extraord!$D:$D,"Lojinha")+SUMIFS(Aut_Ajustes_Manuais!$G:$G,Aut_Ajustes_Manuais!$I:$I,DRE!N$4,Aut_Ajustes_Manuais!$F:$F,"Gifts") | R12: =SUMIFS(T_ORCAMENTOS!$E:$E,T_ORCAMENTOS!$C:$C,"Gifts",T_ORCAMENTOS!$H:$H,"4/2026") | S12: =SUMIFS(Aut_Faturamento_Zig!$F:$F,Aut_Faturamento_Zig!$E:$E,"Gifts",Aut_Faturamento_Zig!$D:$D,DRE!Q$4)+SUMIFS(Aut_Receitas_Extraord!$L:$L,Aut_Receitas_Extraord!$U:$U,DRE!Q$4,Aut_Receitas_Extraord!$D:$D,"Lojinha")+SUMIFS(Aut_Ajustes_Manuais!$G:$G,Aut_Ajustes_Manuais!$I:$I,DRE!Q$4,Aut_Ajustes_Manuais!$F:$F,"Gifts") | U12: =SUMIFS(T_ORCAMENTOS!$E:$E,T_ORCAMENTOS!$C:$C,"Gifts",T_ORCAMENTOS!$H:$H,"5/2026") | V12: =SUMIFS(Aut_Faturamento_Zig!$F:$F,Aut_Faturamento_Zig!$E:$E,"Gifts",Aut_Faturamento_Zig!$D:$D,DRE!T$4)+SUMIFS(Aut_Receitas_Extraord!$L:$L,Aut_Receitas_Extraord!$U:$U,DRE!T$4,Aut_Receitas_Extraord!$D:$D,"Lojinha")+SUMIFS(Aut_Ajustes_Manuais!$G:$G,Aut_Ajustes_Manuais!$I:$I,DRE!T$4,Aut_Ajustes_Manuais!$F:$F,"Gifts") | X12: =SUMIFS(T_ORCAMENTOS!$E:$E,T_ORCAMENTOS!$C:$C,"Gifts",T_ORCAMENTOS!$H:$H,"6/2026") | Y12: =SUMIFS(Aut_Faturamento_Zig!$F:$F,Aut_Faturamento_Zig!$E:$E,"Gifts",Aut_Faturamento_Zig!$D:$D,DRE!W$4)+SUMIFS(Aut_Receitas_Extraord!$L:$L,Aut_Receitas_Extraord!$U:$U,DRE!W$4,Aut_Receitas_Extraord!$D:$D,"Lojinha")+SUMIFS(Aut_Ajustes_Manuais!$G:$G,Aut_Ajustes_Manuais!$I:$I,DRE!W$4,Aut_Ajustes_Manuais!$F:$F,"Gifts") | AA12: =SUMIFS(T_ORCAMENTOS!$E:$E,T_ORCAMENTOS!$C:$C,"Gifts",T_ORCAMENTOS!$H:$H,"7/2026") | AB12: =SUMIFS(Aut_Faturamento_Zig!$F:$F,Aut_Faturamento_Zig!$E:$E,"Gifts",Aut_Faturamento_Zig!$D:$D,DRE!Z$4)+SUMIFS(Aut_Receitas_Extraord!$L:$L,Aut_Receitas_Extraord!$U:$U,DRE!Z$4,Aut_Receitas_Extraord!$D:$D,"Lojinha")+SUMIFS(Aut_Ajustes_Manuais!$G:$G,Aut_Ajustes_Manuais!$I:$I,DRE!Z$4,Aut_Ajustes_Manuais!$F:$F,"Gifts") | AD12: =SUMIFS(T_ORCAMENTOS!$E:$E,T_ORCAMENTOS!$C:$C,"Gifts",T_ORCAMENTOS!$H:$H,"8/2026") | AE12: =SUMIFS(Aut_Faturamento_Zig!$F:$F,Aut_Faturamento_Zig!$E:$E,"Gifts",Aut_Faturamento_Zig!$D:$D,DRE!AC$4)+SUMIFS(Aut_Receitas_Extraord!$L:$L,Aut_Receitas_Extraord!$U:$U,DRE!AC$4,Aut_Receitas_Extraord!$D:$D,"Lojinha")+SUMIFS(Aut_Ajustes_Manuais!$G:$G,Aut_Ajustes_Manuais!$I:$I,DRE!AC$4,Aut_Ajustes_Manuais!$F:$F,"Gifts") | AG12: =SUMIFS(T_ORCAMENTOS!$E:$E,T_ORCAMENTOS!$C:$C,"Gifts",T_ORCAMENTOS!$H:$H,"9/2026") | AH12: =SUMIFS(Aut_Faturamento_Zig!$F:$F,Aut_Faturamento_Zig!$E:$E,"Gifts",Aut_Faturamento_Zig!$D:$D,DRE!AF$4)+SUMIFS(Aut_Receitas_Extraord!$L:$L,Aut_Receitas_Extraord!$U:$U,DRE!AF$4,Aut_Receitas_Extraord!$D:$D,"Lojinha")+SUMIFS(Aut_Ajustes_Manuais!$G:$G,Aut_Ajustes_Manuais!$I:$I,DRE!AF$4,Aut_Ajustes_Manuais!$F:$F,"Gifts") | AJ12: =SUMIFS(T_ORCAMENTOS!$E:$E,T_ORCAMENTOS!$C:$C,"Gifts",T_ORCAMENTOS!$H:$H,"10/2026") | AK12: =SUMIFS(Aut_Faturamento_Zig!$F:$F,Aut_Faturamento_Zig!$E:$E,"Gifts",Aut_Faturamento_Zig!$D:$D,DRE!AI$4)+SUMIFS(Aut_Receitas_Extraord!$L:$L,Aut_Receitas_Extraord!$U:$U,DRE!AI$4,Aut_Receitas_Extraord!$D:$D,"Lojinha")+SUMIFS(Aut_Ajustes_Manuais!$G:$G,Aut_Ajustes_Manuais!$I:$I,DRE!AI$4,Aut_Ajustes_Manuais!$F:$F,"Gifts") | AM12: =SUMIFS(T_ORCAMENTOS!$E:$E,T_ORCAMENTOS!$C:$C,"Gifts",T_ORCAMENTOS!$H:$H,"11/2026") | AN12: =SUMIFS(Aut_Faturamento_Zig!$F:$F,Aut_Faturamento_Zig!$E:$E,"Gifts",Aut_Faturamento_Zig!$D:$D,DRE!AL$4)+SUMIFS(Aut_Receitas_Extraord!$L:$L,Aut_Receitas_Extraord!$U:$U,DRE!AL$4,Aut_Receitas_Extraord!$D:$D,"Lojinha")+SUMIFS(Aut_Ajustes_Manuais!$G:$G,Aut_Ajustes_Manuais!$I:$I,DRE!AL$4,Aut_Ajustes_Manuais!$F:$F,"Gifts") | AP12: =SUMIFS(T_ORCAMENTOS!$E:$E,T_ORCAMENTOS!$C:$C,"Gifts",T_ORCAMENTOS!$H:$H,"12/2026") | AQ12: =SUMIFS(Aut_Faturamento_Zig!$F:$F,Aut_Faturamento_Zig!$E:$E,"Gifts",Aut_Faturamento_Zig!$D:$D,DRE!AO$4)+SUMIFS(Aut_Receitas_Extraord!$L:$L,Aut_Receitas_Extraord!$U:$U,DRE!AO$4,Aut_Receitas_Extraord!$D:$D,"Lojinha")+SUMIFS(Aut_Ajustes_Manuais!$G:$G,Aut_Ajustes_Manuais!$I:$I,DRE!AO$4,Aut_Ajustes_Manuais!$F:$F,"Gifts") | AR12: =SUMIFS($H12:$AO12,$H$5:$AO$5,"<"&MONTH(TODAY()),$H$6:$AO$6,"REAL 25") | AS12: =SUMIFS($I12:$AP12,$I$5:$AP$5,"<"&MONTH(TODAY()),$I$6:$AP$6,"ORÇADO ") | AT12: =SUMIFS($J12:$AQ12,$J$5:$AQ$5,"<"&MONTH(TODAY()),$J$6:$AQ$6,"REAL 26") | AU12: =SUM(H12,K12,N12,Q12,T12,W12,Z12,AC12,AF12,AI12,AL12,AO12) | AV12: =SUM(I12,L12,O12,R12,U12,X12,AA12,AD12,AG12,AJ12,AM12,AP12) | AW12: =SUM(J12,M12,P12,S12,V12,Y12,AB12,AE12,AH12,AK12,AN12,AQ12) | AX12: =SUM(H12,K12,N12) | AY12: =SUM(I12,L12,O12) | AZ12: =SUM(J12,M12,P12) | BA12: =SUM(Q12,T12,W12) | BB12: =SUM(R12,U12,X12) | BC12: =SUM(S12,V12,Y12) | BD12: =SUM(Z12,AC12,AF12) | BE12: =SUM(AA12,AD12,AG12) | BF12: =SUM(AB12,AE12,AH12) | BG12: =SUM(AI12,AL12,AO12) | BH12: =SUM(AJ12,AM12,AP12) | BI12: =SUM(AK12,AN12,AQ12)
A13: Serviço | C13: Estim. Mensal | D13: Gorjeta Fórmula | E13: 13% sobre A&B&C | I13: =SUMIFS(T_ORCAMENTOS!$E:$E,T_ORCAMENTOS!$C:$C,"Serviço",T_ORCAMENTOS!$H:$H,"1/2026") | J13: =SUMIFS(Aut_Faturamento_Zig!$F:$F,Aut_Faturamento_Zig!$E:$E,"Serviço",Aut_Faturamento_Zig!$D:$D,DRE!H$4)+SUMIFS(Aut_Ajustes_Manuais!$G:$G,Aut_Ajustes_Manuais!$I:$I,DRE!H$4,Aut_Ajustes_Manuais!$F:$F,"Serviço") | L13: =SUMIFS(T_ORCAMENTOS!$E:$E,T_ORCAMENTOS!$C:$C,"Serviço",T_ORCAMENTOS!$H:$H,"2/2026") | M13: =SUMIFS(Aut_Faturamento_Zig!$F:$F,Aut_Faturamento_Zig!$E:$E,"Serviço",Aut_Faturamento_Zig!$D:$D,DRE!K$4)+SUMIFS(Aut_Ajustes_Manuais!$G:$G,Aut_Ajustes_Manuais!$I:$I,DRE!K$4,Aut_Ajustes_Manuais!$F:$F,"Serviço") | O13: =SUMIFS(T_ORCAMENTOS!$E:$E,T_ORCAMENTOS!$C:$C,"Serviço",T_ORCAMENTOS!$H:$H,"3/2026") | P13: =SUMIFS(Aut_Faturamento_Zig!$F:$F,Aut_Faturamento_Zig!$E:$E,"Serviço",Aut_Faturamento_Zig!$D:$D,DRE!N$4)+SUMIFS(Aut_Ajustes_Manuais!$G:$G,Aut_Ajustes_Manuais!$I:$I,DRE!N$4,Aut_Ajustes_Manuais!$F:$F,"Serviço") | R13: =SUMIFS(T_ORCAMENTOS!$E:$E,T_ORCAMENTOS!$C:$C,"Serviço",T_ORCAMENTOS!$H:$H,"4/2026") | S13: =SUMIFS(Aut_Faturamento_Zig!$F:$F,Aut_Faturamento_Zig!$E:$E,"Serviço",Aut_Faturamento_Zig!$D:$D,DRE!Q$4)+SUMIFS(Aut_Ajustes_Manuais!$G:$G,Aut_Ajustes_Manuais!$I:$I,DRE!Q$4,Aut_Ajustes_Manuais!$F:$F,"Serviço") | U13: =SUMIFS(T_ORCAMENTOS!$E:$E,T_ORCAMENTOS!$C:$C,"Serviço",T_ORCAMENTOS!$H:$H,"5/2026") | V13: =SUMIFS(Aut_Faturamento_Zig!$F:$F,Aut_Faturamento_Zig!$E:$E,"Serviço",Aut_Faturamento_Zig!$D:$D,DRE!T$4)+SUMIFS(Aut_Ajustes_Manuais!$G:$G,Aut_Ajustes_Manuais!$I:$I,DRE!T$4,Aut_Ajustes_Manuais!$F:$F,"Serviço") | X13: =SUMIFS(T_ORCAMENTOS!$E:$E,T_ORCAMENTOS!$C:$C,"Serviço",T_ORCAMENTOS!$H:$H,"6/2026") | Y13: =SUMIFS(Aut_Faturamento_Zig!$F:$F,Aut_Faturamento_Zig!$E:$E,"Serviço",Aut_Faturamento_Zig!$D:$D,DRE!W$4)+SUMIFS(Aut_Ajustes_Manuais!$G:$G,Aut_Ajustes_Manuais!$I:$I,DRE!W$4,Aut_Ajustes_Manuais!$F:$F,"Serviço") | AA13: =SUMIFS(T_ORCAMENTOS!$E:$E,T_ORCAMENTOS!$C:$C,"Serviço",T_ORCAMENTOS!$H:$H,"7/2026") | AB13: =SUMIFS(Aut_Faturamento_Zig!$F:$F,Aut_Faturamento_Zig!$E:$E,"Serviço",Aut_Faturamento_Zig!$D:$D,DRE!Z$4)+SUMIFS(Aut_Ajustes_Manuais!$G:$G,Aut_Ajustes_Manuais!$I:$I,DRE!Z$4,Aut_Ajustes_Manuais!$F:$F,"Serviço") | AD13: =SUMIFS(T_ORCAMENTOS!$E:$E,T_ORCAMENTOS!$C:$C,"Serviço",T_ORCAMENTOS!$H:$H,"8/2026") | AE13: =SUMIFS(Aut_Faturamento_Zig!$F:$F,Aut_Faturamento_Zig!$E:$E,"Serviço",Aut_Faturamento_Zig!$D:$D,DRE!AC$4)+SUMIFS(Aut_Ajustes_Manuais!$G:$G,Aut_Ajustes_Manuais!$I:$I,DRE!AC$4,Aut_Ajustes_Manuais!$F:$F,"Serviço") | AG13: =SUMIFS(T_ORCAMENTOS!$E:$E,T_ORCAMENTOS!$C:$C,"Serviço",T_ORCAMENTOS!$H:$H,"9/2026") | AH13: =SUMIFS(Aut_Faturamento_Zig!$F:$F,Aut_Faturamento_Zig!$E:$E,"Serviço",Aut_Faturamento_Zig!$D:$D,DRE!AF$4)+SUMIFS(Aut_Ajustes_Manuais!$G:$G,Aut_Ajustes_Manuais!$I:$I,DRE!AF$4,Aut_Ajustes_Manuais!$F:$F,"Serviço") | AJ13: =SUMIFS(T_ORCAMENTOS!$E:$E,T_ORCAMENTOS!$C:$C,"Serviço",T_ORCAMENTOS!$H:$H,"10/2026") | AK13: =SUMIFS(Aut_Faturamento_Zig!$F:$F,Aut_Faturamento_Zig!$E:$E,"Serviço",Aut_Faturamento_Zig!$D:$D,DRE!AI$4)+SUMIFS(Aut_Ajustes_Manuais!$G:$G,Aut_Ajustes_Manuais!$I:$I,DRE!AI$4,Aut_Ajustes_Manuais!$F:$F,"Serviço") | AM13: =SUMIFS(T_ORCAMENTOS!$E:$E,T_ORCAMENTOS!$C:$C,"Serviço",T_ORCAMENTOS!$H:$H,"11/2026") | AN13: =SUMIFS(Aut_Faturamento_Zig!$F:$F,Aut_Faturamento_Zig!$E:$E,"Serviço",Aut_Faturamento_Zig!$D:$D,DRE!AL$4)+SUMIFS(Aut_Ajustes_Manuais!$G:$G,Aut_Ajustes_Manuais!$I:$I,DRE!AL$4,Aut_Ajustes_Manuais!$F:$F,"Serviço") | AP13: =SUMIFS(T_ORCAMENTOS!$E:$E,T_ORCAMENTOS!$C:$C,"Serviço",T_ORCAMENTOS!$H:$H,"12/2026") | AQ13: =SUMIFS(Aut_Faturamento_Zig!$F:$F,Aut_Faturamento_Zig!$E:$E,"Serviço",Aut_Faturamento_Zig!$D:$D,DRE!AO$4)+SUMIFS(Aut_Ajustes_Manuais!$G:$G,Aut_Ajustes_Manuais!$I:$I,DRE!AO$4,Aut_Ajustes_Manuais!$F:$F,"Serviço") | AR13: =SUMIFS($H13:$AO13,$H$5:$AO$5,"<"&MONTH(TODAY()),$H$6:$AO$6,"REAL 25") | AS13: =SUMIFS($I13:$AP13,$I$5:$AP$5,"<"&MONTH(TODAY()),$I$6:$AP$6,"ORÇADO ") | AT13: =SUMIFS($J13:$AQ13,$J$5:$AQ$5,"<"&MONTH(TODAY()),$J$6:$AQ$6,"REAL 26") | AU13: =SUM(H13,K13,N13,Q13,T13,W13,Z13,AC13,AF13,AI13,AL13,AO13) | AV13: =SUM(I13,L13,O13,R13,U13,X13,AA13,AD13,AG13,AJ13,AM13,AP13) | AW13: =SUM(J13,M13,P13,S13,V13,Y13,AB13,AE13,AH13,AK13,AN13,AQ13) | AX13: =SUM(H13,K13,N13) | AY13: =SUM(I13,L13,O13) | AZ13: =SUM(J13,M13,P13) | BA13: =SUM(Q13,T13,W13) | BB13: =SUM(R13,U13,X13) | BC13: =SUM(S13,V13,Y13) | BD13: =SUM(Z13,AC13,AF13) | BE13: =SUM(AA13,AD13,AG13) | BF13: =SUM(AB13,AE13,AH13) | BG13: =SUM(AI13,AL13,AO13) | BH13: =SUM(AJ13,AM13,AP13) | BI13: =SUM(AK13,AN13,AQ13)
A14: Eventos A&B | C14: Estim. Mensal | D14: Preencher base de Eventos | I14: =SUMIFS(T_ORCAMENTOS!$E:$E,T_ORCAMENTOS!$C:$C,"Eventos A&B",T_ORCAMENTOS!$H:$H,"1/2026") | J14: =SUMIFS(BD_Eventos_Novo!$J:$J,BD_Eventos_Novo!$AB:$AB,DRE!H$4)+SUMIFS(BD_Eventos_Novo!$K:$K,BD_Eventos_Novo!$AB:$AB,DRE!H$4)+SUMIFS(Aut_Ajustes_Manuais!$G:$G,Aut_Ajustes_Manuais!$I:$I,DRE!H$4,Aut_Ajustes_Manuais!$F:$F,"Eventos A&B") | L14: =SUMIFS(T_ORCAMENTOS!$E:$E,T_ORCAMENTOS!$C:$C,"Eventos A&B",T_ORCAMENTOS!$H:$H,"2/2026") | M14: =SUMIFS(BD_Eventos_Novo!$J:$J,BD_Eventos_Novo!$AB:$AB,DRE!K$4)+SUMIFS(BD_Eventos_Novo!$K:$K,BD_Eventos_Novo!$AB:$AB,DRE!K$4)+SUMIFS(Aut_Ajustes_Manuais!$G:$G,Aut_Ajustes_Manuais!$I:$I,DRE!K$4,Aut_Ajustes_Manuais!$F:$F,"Eventos A&B") | O14: =SUMIFS(T_ORCAMENTOS!$E:$E,T_ORCAMENTOS!$C:$C,"Eventos A&B",T_ORCAMENTOS!$H:$H,"3/2026") | P14: =SUMIFS(BD_Eventos_Novo!$J:$J,BD_Eventos_Novo!$AB:$AB,DRE!N$4)+SUMIFS(BD_Eventos_Novo!$K:$K,BD_Eventos_Novo!$AB:$AB,DRE!N$4)+SUMIFS(Aut_Ajustes_Manuais!$G:$G,Aut_Ajustes_Manuais!$I:$I,DRE!N$4,Aut_Ajustes_Manuais!$F:$F,"Eventos A&B") | R14: =SUMIFS(T_ORCAMENTOS!$E:$E,T_ORCAMENTOS!$C:$C,"Eventos A&B",T_ORCAMENTOS!$H:$H,"4/2026") | S14: =SUMIFS(BD_Eventos_Novo!$J:$J,BD_Eventos_Novo!$AB:$AB,DRE!Q$4)+SUMIFS(BD_Eventos_Novo!$K:$K,BD_Eventos_Novo!$AB:$AB,DRE!Q$4)+SUMIFS(Aut_Ajustes_Manuais!$G:$G,Aut_Ajustes_Manuais!$I:$I,DRE!Q$4,Aut_Ajustes_Manuais!$F:$F,"Eventos A&B") | U14: =SUMIFS(T_ORCAMENTOS!$E:$E,T_ORCAMENTOS!$C:$C,"Eventos A&B",T_ORCAMENTOS!$H:$H,"5/2026") | V14: =SUMIFS(BD_Eventos_Novo!$J:$J,BD_Eventos_Novo!$AB:$AB,DRE!T$4)+SUMIFS(BD_Eventos_Novo!$K:$K,BD_Eventos_Novo!$AB:$AB,DRE!T$4)+SUMIFS(Aut_Ajustes_Manuais!$G:$G,Aut_Ajustes_Manuais!$I:$I,DRE!T$4,Aut_Ajustes_Manuais!$F:$F,"Eventos A&B") | X14: =SUMIFS(T_ORCAMENTOS!$E:$E,T_ORCAMENTOS!$C:$C,"Eventos A&B",T_ORCAMENTOS!$H:$H,"6/2026") | Y14: =SUMIFS(BD_Eventos_Novo!$J:$J,BD_Eventos_Novo!$AB:$AB,DRE!W$4)+SUMIFS(BD_Eventos_Novo!$K:$K,BD_Eventos_Novo!$AB:$AB,DRE!W$4)+SUMIFS(Aut_Ajustes_Manuais!$G:$G,Aut_Ajustes_Manuais!$I:$I,DRE!W$4,Aut_Ajustes_Manuais!$F:$F,"Eventos A&B") | AA14: =SUMIFS(T_ORCAMENTOS!$E:$E,T_ORCAMENTOS!$C:$C,"Eventos A&B",T_ORCAMENTOS!$H:$H,"7/2026") | AB14: =SUMIFS(BD_Eventos_Novo!$J:$J,BD_Eventos_Novo!$AB:$AB,DRE!Z$4)+SUMIFS(BD_Eventos_Novo!$K:$K,BD_Eventos_Novo!$AB:$AB,DRE!Z$4)+SUMIFS(Aut_Ajustes_Manuais!$G:$G,Aut_Ajustes_Manuais!$I:$I,DRE!Z$4,Aut_Ajustes_Manuais!$F:$F,"Eventos A&B") | AD14: =SUMIFS(T_ORCAMENTOS!$E:$E,T_ORCAMENTOS!$C:$C,"Eventos A&B",T_ORCAMENTOS!$H:$H,"8/2026") | AE14: =SUMIFS(BD_Eventos_Novo!$J:$J,BD_Eventos_Novo!$AB:$AB,DRE!AC$4)+SUMIFS(BD_Eventos_Novo!$K:$K,BD_Eventos_Novo!$AB:$AB,DRE!AC$4)+SUMIFS(Aut_Ajustes_Manuais!$G:$G,Aut_Ajustes_Manuais!$I:$I,DRE!AC$4,Aut_Ajustes_Manuais!$F:$F,"Eventos A&B") | AG14: =SUMIFS(T_ORCAMENTOS!$E:$E,T_ORCAMENTOS!$C:$C,"Eventos A&B",T_ORCAMENTOS!$H:$H,"9/2026") | AH14: =SUMIFS(BD_Eventos_Novo!$J:$J,BD_Eventos_Novo!$AB:$AB,DRE!AF$4)+SUMIFS(BD_Eventos_Novo!$K:$K,BD_Eventos_Novo!$AB:$AB,DRE!AF$4)+SUMIFS(Aut_Ajustes_Manuais!$G:$G,Aut_Ajustes_Manuais!$I:$I,DRE!AF$4,Aut_Ajustes_Manuais!$F:$F,"Eventos A&B") | AJ14: =SUMIFS(T_ORCAMENTOS!$E:$E,T_ORCAMENTOS!$C:$C,"Eventos A&B",T_ORCAMENTOS!$H:$H,"10/2026") | AK14: =SUMIFS(BD_Eventos_Novo!$J:$J,BD_Eventos_Novo!$AB:$AB,DRE!AI$4)+SUMIFS(BD_Eventos_Novo!$K:$K,BD_Eventos_Novo!$AB:$AB,DRE!AI$4)+SUMIFS(Aut_Ajustes_Manuais!$G:$G,Aut_Ajustes_Manuais!$I:$I,DRE!AI$4,Aut_Ajustes_Manuais!$F:$F,"Eventos A&B") | AM14: =SUMIFS(T_ORCAMENTOS!$E:$E,T_ORCAMENTOS!$C:$C,"Eventos A&B",T_ORCAMENTOS!$H:$H,"11/2026") | AN14: =SUMIFS(BD_Eventos_Novo!$J:$J,BD_Eventos_Novo!$AB:$AB,DRE!AL$4)+SUMIFS(BD_Eventos_Novo!$K:$K,BD_Eventos_Novo!$AB:$AB,DRE!AL$4)+SUMIFS(Aut_Ajustes_Manuais!$G:$G,Aut_Ajustes_Manuais!$I:$I,DRE!AL$4,Aut_Ajustes_Manuais!$F:$F,"Eventos A&B") | AP14: =SUMIFS(T_ORCAMENTOS!$E:$E,T_ORCAMENTOS!$C:$C,"Eventos A&B",T_ORCAMENTOS!$H:$H,"12/2026") | AQ14: =SUMIFS(BD_Eventos_Novo!$J:$J,BD_Eventos_Novo!$AB:$AB,DRE!AO$4)+SUMIFS(BD_Eventos_Novo!$K:$K,BD_Eventos_Novo!$AB:$AB,DRE!AO$4)+SUMIFS(Aut_Ajustes_Manuais!$G:$G,Aut_Ajustes_Manuais!$I:$I,DRE!AO$4,Aut_Ajustes_Manuais!$F:$F,"Eventos A&B") | AR14: =SUMIFS($H14:$AO14,$H$5:$AO$5,"<"&MONTH(TODAY()),$H$6:$AO$6,"REAL 25") | AS14: =SUMIFS($I14:$AP14,$I$5:$AP$5,"<"&MONTH(TODAY()),$I$6:$AP$6,"ORÇADO ") | AT14: =SUMIFS($J14:$AQ14,$J$5:$AQ$5,"<"&MONTH(TODAY()),$J$6:$AQ$6,"REAL 26") | AU14: =SUM(H14,K14,N14,Q14,T14,W14,Z14,AC14,AF14,AI14,AL14,AO14) | AV14: =SUM(I14,L14,O14,R14,U14,X14,AA14,AD14,AG14,AJ14,AM14,AP14) | AW14: =SUM(J14,M14,P14,S14,V14,Y14,AB14,AE14,AH14,AK14,AN14,AQ14) | AX14: =SUM(H14,K14,N14) | AY14: =SUM(I14,L14,O14) | AZ14: =SUM(J14,M14,P14) | BA14: =SUM(Q14,T14,W14) | BB14: =SUM(R14,U14,X14) | BC14: =SUM(S14,V14,Y14) | BD14: =SUM(Z14,AC14,AF14) | BE14: =SUM(AA14,AD14,AG14) | BF14: =SUM(AB14,AE14,AH14) | BG14: =SUM(AI14,AL14,AO14) | BH14: =SUM(AJ14,AM14,AP14) | BI14: =SUM(AK14,AN14,AQ14)
A15: Eventos Couvert | C15: Estim. Mensal | D15: Preencher base de Eventos | I15: =SUMIFS(T_ORCAMENTOS!$E:$E,T_ORCAMENTOS!$C:$C,"Eventos Couvert",T_ORCAMENTOS!$H:$H,"1/2026") | J15: =SUMIFS(BD_Eventos_Novo!$M:$M,BD_Eventos_Novo!$AB:$AB,DRE!H$4)+SUMIFS(BD_Eventos_Novo!$N:$N,BD_Eventos_Novo!$AB:$AB,DRE!H$4)+SUMIFS(BD_Eventos_Novo!$O:$O,BD_Eventos_Novo!$AB:$AB,DRE!H$4)+SUMIFS(Aut_Ajustes_Manuais!$G:$G,Aut_Ajustes_Manuais!$I:$I,DRE!H$4,Aut_Ajustes_Manuais!$F:$F,"Eventos Couvert") | L15: =SUMIFS(T_ORCAMENTOS!$E:$E,T_ORCAMENTOS!$C:$C,"Eventos Couvert",T_ORCAMENTOS!$H:$H,"2/2026") | M15: =SUMIFS(BD_Eventos_Novo!$M:$M,BD_Eventos_Novo!$AB:$AB,DRE!K$4)+SUMIFS(BD_Eventos_Novo!$N:$N,BD_Eventos_Novo!$AB:$AB,DRE!K$4)+SUMIFS(BD_Eventos_Novo!$O:$O,BD_Eventos_Novo!$AB:$AB,DRE!K$4)+SUMIFS(Aut_Ajustes_Manuais!$G:$G,Aut_Ajustes_Manuais!$I:$I,DRE!K$4,Aut_Ajustes_Manuais!$F:$F,"Eventos Couvert") | O15: =SUMIFS(T_ORCAMENTOS!$E:$E,T_ORCAMENTOS!$C:$C,"Eventos Couvert",T_ORCAMENTOS!$H:$H,"3/2026") | P15: =SUMIFS(BD_Eventos_Novo!$M:$M,BD_Eventos_Novo!$AB:$AB,DRE!N$4)+SUMIFS(BD_Eventos_Novo!$N:$N,BD_Eventos_Novo!$AB:$AB,DRE!N$4)+SUMIFS(BD_Eventos_Novo!$O:$O,BD_Eventos_Novo!$AB:$AB,DRE!N$4)+SUMIFS(Aut_Ajustes_Manuais!$G:$G,Aut_Ajustes_Manuais!$I:$I,DRE!N$4,Aut_Ajustes_Manuais!$F:$F,"Eventos Couvert") | R15: =SUMIFS(T_ORCAMENTOS!$E:$E,T_ORCAMENTOS!$C:$C,"Eventos Couvert",T_ORCAMENTOS!$H:$H,"4/2026") | S15: =SUMIFS(BD_Eventos_Novo!$M:$M,BD_Eventos_Novo!$AB:$AB,DRE!Q$4)+SUMIFS(BD_Eventos_Novo!$N:$N,BD_Eventos_Novo!$AB:$AB,DRE!Q$4)+SUMIFS(BD_Eventos_Novo!$O:$O,BD_Eventos_Novo!$AB:$AB,DRE!Q$4)+SUMIFS(Aut_Ajustes_Manuais!$G:$G,Aut_Ajustes_Manuais!$I:$I,DRE!Q$4,Aut_Ajustes_Manuais!$F:$F,"Eventos Couvert") | U15: =SUMIFS(T_ORCAMENTOS!$E:$E,T_ORCAMENTOS!$C:$C,"Eventos Couvert",T_ORCAMENTOS!$H:$H,"5/2026") | V15: =SUMIFS(BD_Eventos_Novo!$M:$M,BD_Eventos_Novo!$AB:$AB,DRE!T$4)+SUMIFS(BD_Eventos_Novo!$N:$N,BD_Eventos_Novo!$AB:$AB,DRE!T$4)+SUMIFS(BD_Eventos_Novo!$O:$O,BD_Eventos_Novo!$AB:$AB,DRE!T$4)+SUMIFS(Aut_Ajustes_Manuais!$G:$G,Aut_Ajustes_Manuais!$I:$I,DRE!T$4,Aut_Ajustes_Manuais!$F:$F,"Eventos Couvert") | X15: =SUMIFS(T_ORCAMENTOS!$E:$E,T_ORCAMENTOS!$C:$C,"Eventos Couvert",T_ORCAMENTOS!$H:$H,"6/2026") | Y15: =SUMIFS(BD_Eventos_Novo!$M:$M,BD_Eventos_Novo!$AB:$AB,DRE!W$4)+SUMIFS(BD_Eventos_Novo!$N:$N,BD_Eventos_Novo!$AB:$AB,DRE!W$4)+SUMIFS(BD_Eventos_Novo!$O:$O,BD_Eventos_Novo!$AB:$AB,DRE!W$4)+SUMIFS(Aut_Ajustes_Manuais!$G:$G,Aut_Ajustes_Manuais!$I:$I,DRE!W$4,Aut_Ajustes_Manuais!$F:$F,"Eventos Couvert") | AA15: =SUMIFS(T_ORCAMENTOS!$E:$E,T_ORCAMENTOS!$C:$C,"Eventos Couvert",T_ORCAMENTOS!$H:$H,"7/2026") | AB15: =SUMIFS(BD_Eventos_Novo!$M:$M,BD_Eventos_Novo!$AB:$AB,DRE!Z$4)+SUMIFS(BD_Eventos_Novo!$N:$N,BD_Eventos_Novo!$AB:$AB,DRE!Z$4)+SUMIFS(BD_Eventos_Novo!$O:$O,BD_Eventos_Novo!$AB:$AB,DRE!Z$4)+SUMIFS(Aut_Ajustes_Manuais!$G:$G,Aut_Ajustes_Manuais!$I:$I,DRE!Z$4,Aut_Ajustes_Manuais!$F:$F,"Eventos Couvert") | AD15: =SUMIFS(T_ORCAMENTOS!$E:$E,T_ORCAMENTOS!$C:$C,"Eventos Couvert",T_ORCAMENTOS!$H:$H,"8/2026") | AE15: =SUMIFS(BD_Eventos_Novo!$M:$M,BD_Eventos_Novo!$AB:$AB,DRE!AC$4)+SUMIFS(BD_Eventos_Novo!$N:$N,BD_Eventos_Novo!$AB:$AB,DRE!AC$4)+SUMIFS(BD_Eventos_Novo!$O:$O,BD_Eventos_Novo!$AB:$AB,DRE!AC$4)+SUMIFS(Aut_Ajustes_Manuais!$G:$G,Aut_Ajustes_Manuais!$I:$I,DRE!AC$4,Aut_Ajustes_Manuais!$F:$F,"Eventos Couvert") | AG15: =SUMIFS(T_ORCAMENTOS!$E:$E,T_ORCAMENTOS!$C:$C,"Eventos Couvert",T_ORCAMENTOS!$H:$H,"9/2026") | AH15: =SUMIFS(BD_Eventos_Novo!$M:$M,BD_Eventos_Novo!$AB:$AB,DRE!AF$4)+SUMIFS(BD_Eventos_Novo!$N:$N,BD_Eventos_Novo!$AB:$AB,DRE!AF$4)+SUMIFS(BD_Eventos_Novo!$O:$O,BD_Eventos_Novo!$AB:$AB,DRE!AF$4)+SUMIFS(Aut_Ajustes_Manuais!$G:$G,Aut_Ajustes_Manuais!$I:$I,DRE!AF$4,Aut_Ajustes_Manuais!$F:$F,"Eventos Couvert") | AJ15: =SUMIFS(T_ORCAMENTOS!$E:$E,T_ORCAMENTOS!$C:$C,"Eventos Couvert",T_ORCAMENTOS!$H:$H,"10/2026") | AK15: =SUMIFS(BD_Eventos_Novo!$M:$M,BD_Eventos_Novo!$AB:$AB,DRE!AI$4)+SUMIFS(BD_Eventos_Novo!$N:$N,BD_Eventos_Novo!$AB:$AB,DRE!AI$4)+SUMIFS(BD_Eventos_Novo!$O:$O,BD_Eventos_Novo!$AB:$AB,DRE!AI$4)+SUMIFS(Aut_Ajustes_Manuais!$G:$G,Aut_Ajustes_Manuais!$I:$I,DRE!AI$4,Aut_Ajustes_Manuais!$F:$F,"Eventos Couvert") | AM15: =SUMIFS(T_ORCAMENTOS!$E:$E,T_ORCAMENTOS!$C:$C,"Eventos Couvert",T_ORCAMENTOS!$H:$H,"11/2026") | AN15: =SUMIFS(BD_Eventos_Novo!$M:$M,BD_Eventos_Novo!$AB:$AB,DRE!AL$4)+SUMIFS(BD_Eventos_Novo!$N:$N,BD_Eventos_Novo!$AB:$AB,DRE!AL$4)+SUMIFS(BD_Eventos_Novo!$O:$O,BD_Eventos_Novo!$AB:$AB,DRE!AL$4)+SUMIFS(Aut_Ajustes_Manuais!$G:$G,Aut_Ajustes_Manuais!$I:$I,DRE!AL$4,Aut_Ajustes_Manuais!$F:$F,"Eventos Couvert") | AP15: =SUMIFS(T_ORCAMENTOS!$E:$E,T_ORCAMENTOS!$C:$C,"Eventos Couvert",T_ORCAMENTOS!$H:$H,"12/2026") | AQ15: =SUMIFS(BD_Eventos_Novo!$M:$M,BD_Eventos_Novo!$AB:$AB,DRE!AO$4)+SUMIFS(BD_Eventos_Novo!$N:$N,BD_Eventos_Novo!$AB:$AB,DRE!AO$4)+SUMIFS(BD_Eventos_Novo!$O:$O,BD_Eventos_Novo!$AB:$AB,DRE!AO$4)+SUMIFS(Aut_Ajustes_Manuais!$G:$G,Aut_Ajustes_Manuais!$I:$I,DRE!AO$4,Aut_Ajustes_Manuais!$F:$F,"Eventos Couvert") | AR15: =SUMIFS($H15:$AO15,$H$5:$AO$5,"<"&MONTH(TODAY()),$H$6:$AO$6,"REAL 25") | AS15: =SUMIFS($I15:$AP15,$I$5:$AP$5,"<"&MONTH(TODAY()),$I$6:$AP$6,"ORÇADO ") | AT15: =SUMIFS($J15:$AQ15,$J$5:$AQ$5,"<"&MONTH(TODAY()),$J$6:$AQ$6,"REAL 26") | AU15: =SUM(H15,K15,N15,Q15,T15,W15,Z15,AC15,AF15,AI15,AL15,AO15) | AV15: =SUM(I15,L15,O15,R15,U15,X15,AA15,AD15,AG15,AJ15,AM15,AP15) | AW15: =SUM(J15,M15,P15,S15,V15,Y15,AB15,AE15,AH15,AK15,AN15,AQ15) | AX15: =SUM(H15,K15,N15) | AY15: =SUM(I15,L15,O15) | AZ15: =SUM(J15,M15,P15) | BA15: =SUM(Q15,T15,W15) | BB15: =SUM(R15,U15,X15) | BC15: =SUM(S15,V15,Y15) | BD15: =SUM(Z15,AC15,AF15) | BE15: =SUM(AA15,AD15,AG15) | BF15: =SUM(AB15,AE15,AH15) | BG15: =SUM(AI15,AL15,AO15) | BH15: =SUM(AJ15,AM15,AP15) | BI15: =SUM(AK15,AN15,AQ15)
